Workbook

Sheet 1_Расчет
D1: 1 | E1: =D1+1 -> 2 | F1: =E1+1 -> 3 | G1: =F1+1 -> 4 | H1: =G1+1 -> 5 | I1: =H1+1 -> 6 | J1: =I1+1 -> 7 | K1: =J1+1 -> 8 | L1: =K1+1 -> 9 | ... BP1: =BO1+1 -> 65
C2: + | D2: + | K2: + | L2: + | M2: + | N2: + | O2: + | P2: + | Q2: + | R2: + | S2: + | T2: + | U2: + | V2: + | W2: + | X2: + | Y2: + | Z2: + | AA2: + | AB2: + | AC2: + | AD2: + | AE2: + | AF2: + | AG2: + | AH2: + | AI2: + | AK2: + | AL2: + | AM2: + | AN2: + | AO2: + | AQ2: + | AR2: + | AS2: + | AT2: + | AU2: + | AX2: + | AY2: + | AZ2: + | BA2: + | BB2: + | BF2: + | BH2: +
AX3: 0.5 | BE3: 0.5 | BL3: 0.5 | BN3: 0.5
O4: 0.15 | T4: 0.15 | Y4: 0.35 | AD4: 0.35 | AK4: 0.15 | AQ4: 0.15 | AX4: 0.35 | BE4: 0.35
C5: № пп. | D5: ОМСУ | E5: Что снабжаем в ОМСУ МОЭ | G5: Что снабжаем в ОМСУ РМР | I5: Доля сетей в ОМСУ | J5: Кол-во жителей в ОМСУ | K5: Количество отключений на новый год, шт. | P5: Жалобы на электроснабжения в новый год, шт. | U5: Количество отключений в целом за год, шт. | Z5: Жалобы на электроснабжение | AE5: Итоговый рейтинг ОМСУ по надежности и качеству электроснабжения (1 - самый плохой) | AF5: Количество отключений на новый год, шт. на 10 тыс. жителей | AL5: Жалобы на электроснабжения в новый год, шт. на 10 тыс. жителей | AR5: Количество отключений в целом за год, шт. на 10 тыс. жителей | AY5: Жалобы на электроснабжение на 10 тыс. чел. | BF5: Итоговый рейтинг ОМСУ по надежности и качеству электроснабжения (1 - самый плохой) | BH5: Итоговый рейтинг ОМСУ по надежности и качеству электроснабжения (1 - самый плохой) | BI5: Итоговый рейтинг ОМСУ по надежности и качеству электроснабжения (1 - самый плохой) (по откл. и жалобам за год) | BL5: Разница (2025 - 2024) | BP5: Итоговый рейтинг топ лучших ОМСУ по динамике в 2025 г. относительно 2024 г.
E6: Доля сетей в ОМСУ | F6: Описание | G6: Доля сетей в ОМСУ | H6: Перечисление | K6: 2024 / 2025 | L6: 2025 / 2026 | M6: Разница (2026 - 2025) | O6: Ранг по количеству отключений за НГ | P6: 2024/2025 | Q6: 2025/2026 | R6: Разница (2026 - 2025) | T6: Ранг по кол-ву жалоб за НГ | U6: 2024 | V6: 2025 | W6: Разница (2025 - 2024) | Y6: Ранг по кол-ву откл. в 2025 г. | Z6: 2024 | AA6: 2025 | AB6: Разница (2025 - 2024) | AD6: Ранг по кол-ву жалоб в 2025 г. | AF6: 2024 / 2025 | AG6: 2025 / 2026 | AH6: Разница (2026 - 2025) | AJ6: Жалобы (приведенные к кол-ву населения) | AK6: Ранг по количеству отключений за НГ | AL6: 2024/2025 | AM6: 2025/2026 | AN6: Разница (2026 - 2025) | AP6: Жалобы (приведенные к кол-ву населения) | AQ6: Ранг по кол-ву жалоб за НГ | AR6: 2024 | AS6: 2025 | AT6: Разница (2025 - 2024) | AV6: Отключения (приведенные к кол-ву населения) | AW6: Нормализация | AX6: Ранг по кол-ву откл. в 2025 г. (с учетом жителей) | AY6: 2024 | AZ6: 2025 | BA6: Разница (2025 - 2024) | BC6: Жалобы (приведенные к кол-ву населения) | BD6: Нормализация | BE6: Ранг по кол-ву жалоб в 2025 г. (с учетом жителей) | BJ6: Расчет с учетом нормализации | BK6: Ранг с учетом нормализации | BL6: откл., приведенная к кол-ву жителей | BM6: ранг (0 - хорошо) | BN6: жалоб., приведенная к кол-ву жителей | BO6: ранг (0 - хорошо)
E7: % | F7: - | G7: % | H7: - | I7: % | K7: шт. | L7: шт. | M7: шт. | N7: % | O7: - | P7: шт. | Q7: шт. | R7: шт. | S7: % | U7: шт. | V7: шт. | W7: шт. | X7: % | Y7: - | Z7: шт. | AA7: шт. | AB7: шт. | AC7: % | AD7: - | AF7: шт. | AG7: шт. | AH7: шт. | AI7: % | AK7: - | AL7: шт. | AM7: шт. | AN7: шт. | AO7: % | AR7: шт. | AS7: шт. | AT7: шт. | AU7: % | AX7: - | AY7: шт. | AZ7: шт. | BA7: шт. | BB7: %
D8: Балашиха | I8: 10 | J8: 549846 | K8: 35 | L8: 39 | M8: 4 | N8: =IFERROR(M8/K8,"-") -> 0.11428571 | O8: =_xlfn.RANK.EQ(L8,L$8:L$63,0) -> 3 | P8: 15 | Q8: 19 | R8: =Q8-P8 -> 4 | S8: =IFERROR(R8/P8,"-") -> 0.26666667 | T8: =_xlfn.RANK.EQ(Q8,Q$8:Q$63,0) -> 10 | U8: 258 | V8: 203 | W8: =V8-U8 -> -55 | X8: =IFERROR(W8/U8,"-") -> -0.21317829 | Y8: =_xlfn.RANK.EQ(V8,V$8:V$63,0) -> 20 | Z8: 757 | AA8: 581 | AB8: =AA8-Z8 -> -176 | AC8: =IFERROR(AB8/Z8,"-") -> -0.2324967 | AD8: =_xlfn.RANK.EQ(AA8,AA$8:AA$63,0) -> 19 | AE8: =O8*O$4+T8*T$4+Y8*Y$4+AD8*AD$4 -> 15.6 | AF8: =K8 -> 35 | AG8: =L8 -> 39 | AH8: =AG8-AF8 -> 4 | AI8: =IFERROR(AH8/AF8,"-") -> 0.11428571 | AJ8: =10000*AG8/J8 -> 0.70928951 | AK8: =_xlfn.RANK.EQ(AJ8,AJ$8:AJ$63,0) -> 26 | AL8: =P8 -> 15 | AM8: =Q8 -> 19 | AN8: =AM8-AL8 -> 4 | AO8: =IFERROR(AN8/AL8,"-") -> 0.26666667 | AP8: =10000*AM8/J8 -> 0.3455513 | AQ8: =_xlfn.RANK.EQ(AP8,AP$8:AP$63,0) -> 27 | AR8: 258 | AS8: 203 | AT8: =AS8-AR8 -> -55 | AU8: =IFERROR(AT8/AR8,"-") -> -0.21317829 | AV8: =10000*AS8/J8 -> 3.6919428 | AW8: =IFERROR(MAX(AV$8:AV$63)/(MAX(AV$8:AV$63)-AV8)*5,0) -> 5.4710031 | AX8: =_xlfn.RANK.EQ(AV8,AV$8:AV$63,0) -> 45 | AY8: 757 | AZ8: 581 | BA8: =AZ8-AY8 -> -176 | BB8: =IFERROR(BA8/AY8,"-") -> -0.2324967 | BC8: =AZ8*10000/J8 -> 10.566595 | BD8: =(MAX(BC$8:BC$63)-BC8)/MAX(BC$8:BC$63)*5 -> 4.6059279 | BE8: =_xlfn.RANK.EQ(BC8,BC$8:BC$63,0) -> 48 | BF8: =AK8*AK$4+AQ8*AQ$4+AX8*AX$4+BE8*BE$4 -> 40.5 | BH8: =AX$4*AX8+BE8*BE$4 -> 32.55 | BI8: =AX$3*AX8+BE$3*BE8 -> 46.5 | BJ8: =AW8*AX$3+BD8*BE$3 -> 5.0384655 | BK8: =_xlfn.RANK.EQ(BJ8,BJ$8:BJ$63,1) -> 56 | BL8: =AT8/J8*10000 -> -1.0002801 | BM8: =_xlfn.RANK.EQ(BL8,BL$8:BL$63,1) -> 5 | BN8: =BA8/J8*10000 -> -3.2008963 | BO8: =_xlfn.RANK.EQ(BN8,BN$8:BN$63,1) -> 26 | BP8: =BM8*BL$3+BO8*BN$3 -> 15.5
D9: Богородский | I9: 7 | J9: 218485 | K9: 1 | L9: 5 | M9: 4 | N9: =IFERROR(M9/K9,"-") -> 4 | O9: =_xlfn.RANK.EQ(L9,L$8:L$63,0) -> 33 | P9: 10 | Q9: 8 | R9: =Q9-P9 -> -2 | S9: =IFERROR(R9/P9,"-") -> -0.2 | T9: =_xlfn.RANK.EQ(Q9,Q$8:Q$63,0) -> 21 | U9: 201 | V9: 262 | W9: =V9-U9 -> 61 | X9: =IFERROR(W9/U9,"-") -> 0.30348259 | Y9: =_xlfn.RANK.EQ(V9,V$8:V$63,0) -> 13 | Z9: 783 | AA9: 787 | AB9: =AA9-Z9 -> 4 | AC9: =IFERROR(AB9/Z9,"-") -> 0.0051085568 | AD9: =_xlfn.RANK.EQ(AA9,AA$8:AA$63,0) -> 14 | AE9: =O9*O$4+T9*T$4+Y9*Y$4+AD9*AD$4 -> 17.55 | AF9: =K9 -> 1 | AG9: =L9 -> 5 | AH9: =AG9-AF9 -> 4 | AI9: =IFERROR(AH9/AF9,"-") -> 4 | AJ9: =10000*AG9/J9 -> 0.22884866 | AK9: =_xlfn.RANK.EQ(AJ9,AJ$8:AJ$63,0) -> 37 | AL9: =P9 -> 10 | AM9: =Q9 -> 8 | AN9: =AM9-AL9 -> -2 | AO9: =IFERROR(AN9/AL9,"-") -> -0.2 | AP9: =10000*AM9/J9 -> 0.36615786 | AQ9: =_xlfn.RANK.EQ(AP9,AP$8:AP$63,0) -> 26 | AR9: 201 | AS9: 262 | AT9: =AS9-AR9 -> 61 | AU9: =IFERROR(AT9/AR9,"-") -> 0.30348259 | AV9: =10000*AS9/J9 -> 11.99167 | AW9: =(MAX(AV$8:AV$63)-AV9)/MAX(AV$8:AV$63)*5 -> 3.6018574 | AX9: =_xlfn.RANK.EQ(AV9,AV$8:AV$63,0) -> 20 | AY9: 783 | AZ9: 787 | BA9: =AZ9-AY9 -> 4 | BB9: =IFERROR(BA9/AY9,"-") -> 0.0051085568 | BC9: =AZ9*10000/J9 -> 36.020779 | BD9: =(MAX(BC$8:BC$63)-BC9)/MAX(BC$8:BC$63)*5 -> 3.6566359 | BE9: =_xlfn.RANK.EQ(BC9,BC$8:BC$63,0) -> 20 | BF9: =AK9*AK$4+AQ9*AQ$4+AX9*AX$4+BE9*BE$4 -> 23.45 | BH9: =O9*O$4+T9*T$4+AX$4*AX9+BE9*BE$4 -> 22.1 | BI9: =AX$3*AX9+BE$3*BE9 -> 20 | BJ9: =AW9*AX$3+BD9*BE$3 -> 3.6292466 | BK9: =_xlfn.RANK.EQ(BJ9,BJ$8:BJ$63,1) -> 19 | BL9: =AT9/J9*10000 -> 2.7919537 | BM9: =_xlfn.RANK.EQ(BL9,BL$8:BL$63,1) -> 32 | BN9: =BA9/J9*10000 -> 0.18307893 | BO9: =_xlfn.RANK.EQ(BN9,BN$8:BN$63,1) -> 34 | BP9: =BM9*BL$3+BO9*BN$3 -> 33
D10: Электросталь | I10: 15 | J10: 152190 | K10: 2 | L10: 6 | M10: 4 | N10: =IFERROR(M10/K10,"-") -> 2 | O10: =_xlfn.RANK.EQ(L10,L$8:L$63,0) -> 29 | P10: 5 | Q10: 8 | R10: =Q10-P10 -> 3 | S10: =IFERROR(R10/P10,"-") -> 0.6 | T10: =_xlfn.RANK.EQ(Q10,Q$8:Q$63,0) -> 21 | U10: 61 | V10: 52 | W10: =V10-U10 -> -9 | X10: =IFERROR(W10/U10,"-") -> -0.14754098 | Y10: =_xlfn.RANK.EQ(V10,V$8:V$63,0) -> 40 | Z10: 140 | AA10: 114 | AB10: =AA10-Z10 -> -26 | AC10: =IFERROR(AB10/Z10,"-") -> -0.18571429 | AD10: =_xlfn.RANK.EQ(AA10,AA$8:AA$63,0) -> 43 | AE10: =O10*O$4+T10*T$4+Y10*Y$4+AD10*AD$4 -> 36.55 | AF10: =K10 -> 2 | AG10: =L10 -> 6 | AH10: =AG10-AF10 -> 4 | AI10: =IFERROR(AH10/AF10,"-") -> 2 | AJ10: =10000*AG10/J10 -> 0.39424404 | AK10: =_xlfn.RANK.EQ(AJ10,AJ$8:AJ$63,0) -> 34 | AL10: =P10 -> 5 | AM10: =Q10 -> 8 | AN10: =AM10-AL10 -> 3 | AO10: =IFERROR(AN10/AL10,"-") -> 0.6 | AP10: =10000*AM10/J10 -> 0.52565872 | AQ10: =_xlfn.RANK.EQ(AP10,AP$8:AP$63,0) -> 22 | AR10: 61 | AS10: 52 | AT10: =AS10-AR10 -> -9 | AU10: =IFERROR(AT10/AR10,"-") -> -0.14754098 | AV10: =10000*AS10/J10 -> 3.4167817 | AW10: =(MAX(AV$8:AV$63)-AV10)/MAX(AV$8:AV$63)*5 -> 4.6016278 | AX10: =_xlfn.RANK.EQ(AV10,AV$8:AV$63,0) -> 46 | AY10: 140 | AZ10: 114 | BA10: =AZ10-AY10 -> -26 | BB10: =IFERROR(BA10/AY10,"-") -> -0.18571429 | BC10: =AZ10*10000/J10 -> 7.4906367 | BD10: =(MAX(BC$8:BC$63)-BC10)/MAX(BC$8:BC$63)*5 -> 4.7206431 | BE10: =_xlfn.RANK.EQ(BC10,BC$8:BC$63,0) -> 52 | BF10: =AK10*AK$4+AQ10*AQ$4+AX10*AX$4+BE10*BE$4 -> 42.7 | BH10: =O10*O$4+T10*T$4+AX$4*AX10+BE10*BE$4 -> 41.8 | BI10: =AX$3*AX10+BE$3*BE10 -> 49 | BJ10: =AW10*AX$3+BD10*BE$3 -> 4.6611355 | BK10: =_xlfn.RANK.EQ(BJ10,BJ$8:BJ$63,1) -> 49 | BL10: =AT10/J10*10000 -> -0.59136606 | BM10: =_xlfn.RANK.EQ(BL10,BL$8:BL$63,1) -> 9 | BN10: =BA10/J10*10000 -> -1.7083908 | BO10: =_xlfn.RANK.EQ(BN10,BN$8:BN$63,1) -> 29 | BP10: =BM10*BL$3+BO10*BN$3 -> 19
D11: Щелково | I11: 8 | J11: 217794 | K11: 5 | L11: 1 | M11: -4 | N11: =IFERROR(M11/K11,"-") -> -0.8 | O11: =_xlfn.RANK.EQ(L11,L$8:L$63,0) -> 38 | P11: 9 | Q11: 14 | R11: =Q11-P11 -> 5 | S11: =IFERROR(R11/P11,"-") -> 0.55555556 | T11: =_xlfn.RANK.EQ(Q11,Q$8:Q$63,0) -> 16 | U11: 169 | V11: 194 | W11: =V11-U11 -> 25 | X11: =IFERROR(W11/U11,"-") -> 0.14792899 | Y11: =_xlfn.RANK.EQ(V11,V$8:V$63,0) -> 21 | Z11: 515 | AA11: 440 | AB11: =AA11-Z11 -> -75 | AC11: =IFERROR(AB11/Z11,"-") -> -0.14563107 | AD11: =_xlfn.RANK.EQ(AA11,AA$8:AA$63,0) -> 24 | AE11: =O11*O$4+T11*T$4+Y11*Y$4+AD11*AD$4 -> 23.85 | AF11: =K11 -> 5 | AG11: =L11 -> 1 | AH11: =AG11-AF11 -> -4 | AI11: =IFERROR(AH11/AF11,"-") -> -0.8 | AJ11: =10000*AG11/J11 -> 0.045914947 | AK11: =_xlfn.RANK.EQ(AJ11,AJ$8:AJ$63,0) -> 45 | AL11: =P11 -> 9 | AM11: =Q11 -> 14 | AN11: =AM11-AL11 -> 5 | AO11: =IFERROR(AN11/AL11,"-") -> 0.55555556 | AP11: =10000*AM11/J11 -> 0.64280926 | AQ11: =_xlfn.RANK.EQ(AP11,AP$8:AP$63,0) -> 19 | AR11: 169 | AS11: 194 | AT11: =AS11-AR11 -> 25 | AU11: =IFERROR(AT11/AR11,"-") -> 0.14792899 | AV11: =10000*AS11/J11 -> 8.9074997 | AW11: =(MAX(AV$8:AV$63)-AV11)/MAX(AV$8:AV$63)*5 -> 3.9614495 | AX11: =_xlfn.RANK.EQ(AV11,AV$8:AV$63,0) -> 27 | AY11: 515 | AZ11: 440 | BA11: =AZ11-AY11 -> -75 | BB11: =IFERROR(BA11/AY11,"-") -> -0.14563107 | BC11: =AZ11*10000/J11 -> 20.202577 | BD11: =(MAX(BC$8:BC$63)-BC11)/MAX(BC$8:BC$63)*5 -> 4.2465622 | BE11: =_xlfn.RANK.EQ(BC11,BC$8:BC$63,0) -> 37 | BF11: =AK11*AK$4+AQ11*AQ$4+AX11*AX$4+BE11*BE$4 -> 32 | BH11: =O11*O$4+T11*T$4+AX$4*AX11+BE11*BE$4 -> 30.5 | BI11: =AX$3*AX11+BE$3*BE11 -> 32 | BJ11: =AW11*AX$3+BD11*BE$3 -> 4.1040058 | BK11: =_xlfn.RANK.EQ(BJ11,BJ$8:BJ$63,1) -> 34 | BL11: =AT11/J11*10000 -> 1.1478737 | BM11: =_xlfn.RANK.EQ(BL11,BL$8:BL$63,1) -> 20 | BN11: =BA11/J11*10000 -> -3.443621 | BO11: =_xlfn.RANK.EQ(BN11,BN$8:BN$63,1) -> 23 | BP11: =BM11*BL$3+BO11*BN$3 -> 21.5
D12: Орехово-Зуево | I12: 1 | J12: 241038 | K12: 36 | L12: 22 | M12: -14 | N12: =IFERROR(M12/K12,"-") -> -0.38888889 | O12: =_xlfn.RANK.EQ(L12,L$8:L$63,0) -> 16 | P12: 4 | Q12: 5 | R12: =Q12-P12 -> 1 | S12: =IFERROR(R12/P12,"-") -> 0.25 | T12: =_xlfn.RANK.EQ(Q12,Q$8:Q$63,0) -> 27 | U12: 164 | V12: 277 | W12: =V12-U12 -> 113 | X12: =IFERROR(W12/U12,"-") -> 0.68902439 | Y12: =_xlfn.RANK.EQ(V12,V$8:V$63,0) -> 11 | Z12: 550 | AA12: 383 | AB12: =AA12-Z12 -> -167 | AC12: =IFERROR(AB12/Z12,"-") -> -0.30363636 | AD12: =_xlfn.RANK.EQ(AA12,AA$8:AA$63,0) -> 26 | AE12: =O12*O$4+T12*T$4+Y12*Y$4+AD12*AD$4 -> 19.4 | AF12: =K12 -> 36 | AG12: =L12 -> 22 | AH12: =AG12-AF12 -> -14 | AI12: =IFERROR(AH12/AF12,"-") -> -0.38888889 | AJ12: =10000*AG12/J12 -> 0.91271916 | AK12: =_xlfn.RANK.EQ(AJ12,AJ$8:AJ$63,0) -> 19 | AL12: =P12 -> 4 | AM12: =Q12 -> 5 | AN12: =AM12-AL12 -> 1 | AO12: =IFERROR(AN12/AL12,"-") -> 0.25 | AP12: =10000*AM12/J12 -> 0.20743617 | AQ12: =_xlfn.RANK.EQ(AP12,AP$8:AP$63,0) -> 32 | AR12: 164 | AS12: 277 | AT12: =AS12-AR12 -> 113 | AU12: =IFERROR(AT12/AR12,"-") -> 0.68902439 | AV12: =10000*AS12/J12 -> 11.491964 | AW12: =(MAX(AV$8:AV$63)-AV12)/MAX(AV$8:AV$63)*5 -> 3.6601195 | AX12: =_xlfn.RANK.EQ(AV12,AV$8:AV$63,0) -> 22 | AY12: 550 | AZ12: 383 | BA12: =AZ12-AY12 -> -167 | BB12: =IFERROR(BA12/AY12,"-") -> -0.30363636 | BC12: =AZ12*10000/J12 -> 15.889611 | BD12: =(MAX(BC$8:BC$63)-BC12)/MAX(BC$8:BC$63)*5 -> 4.4074106 | BE12: =_xlfn.RANK.EQ(BC12,BC$8:BC$63,0) -> 43 | BF12: =AK12*AK$4+AQ12*AQ$4+AX12*AX$4+BE12*BE$4 -> 30.4 | BH12: =O12*O$4+T12*T$4+AX$4*AX12+BE12*BE$4 -> 29.2 | BI12: =AX$3*AX12+BE$3*BE12 -> 32.5 | BJ12: =AW12*AX$3+BD12*BE$3 -> 4.033765 | BK12: =_xlfn.RANK.EQ(BJ12,BJ$8:BJ$63,1) -> 29 | BL12: =AT12/J12*10000 -> 4.6880575 | BM12: =_xlfn.RANK.EQ(BL12,BL$8:BL$63,1) -> 39 | BN12: =BA12/J12*10000 -> -6.9283681 | BO12: =_xlfn.RANK.EQ(BN12,BN$8:BN$63,1) -> 15 | BP12: =BM12*BL$3+BO12*BN$3 -> 27
D13: Павлово-Посадский | I13: 5 | J13: 121788 | K13: 4 | L13: 1 | M13: -3 | N13: =IFERROR(M13/K13,"-") -> -0.75 | O13: =_xlfn.RANK.EQ(L13,L$8:L$63,0) -> 38 | P13: 33 | Q13: 12 | R13: =Q13-P13 -> -21 | S13: =IFERROR(R13/P13,"-") -> -0.63636364 | T13: =_xlfn.RANK.EQ(Q13,Q$8:Q$63,0) -> 17 | U13: 90 | V13: 108 | W13: =V13-U13 -> 18 | X13: =IFERROR(W13/U13,"-") -> 0.2 | Y13: =_xlfn.RANK.EQ(V13,V$8:V$63,0) -> 30 | Z13: 756 | AA13: 573 | AB13: =AA13-Z13 -> -183 | AC13: =IFERROR(AB13/Z13,"-") -> -0.24206349 | AD13: =_xlfn.RANK.EQ(AA13,AA$8:AA$63,0) -> 20 | AE13: =O13*O$4+T13*T$4+Y13*Y$4+AD13*AD$4 -> 25.75 | AF13: =K13 -> 4 | AG13: =L13 -> 1 | AH13: =AG13-AF13 -> -3 | AI13: =IFERROR(AH13/AF13,"-") -> -0.75 | AJ13: =10000*AG13/J13 -> 0.082109896 | AK13: =_xlfn.RANK.EQ(AJ13,AJ$8:AJ$63,0) -> 44 | AL13: =P13 -> 33 | AM13: =Q13 -> 12 | AN13: =AM13-AL13 -> -21 | AO13: =IFERROR(AN13/AL13,"-") -> -0.63636364 | AP13: =10000*AM13/J13 -> 0.98531875 | AQ13: =_xlfn.RANK.EQ(AP13,AP$8:AP$63,0) -> 13 | AR13: 90 | AS13: 108 | AT13: =AS13-AR13 -> 18 | AU13: =IFERROR(AT13/AR13,"-") -> 0.2 | AV13: =10000*AS13/J13 -> 8.8678688 | AW13: =(MAX(AV$8:AV$63)-AV13)/MAX(AV$8:AV$63)*5 -> 3.9660702 | AX13: =_xlfn.RANK.EQ(AV13,AV$8:AV$63,0) -> 28 | AY13: 756 | AZ13: 573 | BA13: =AZ13-AY13 -> -183 | BB13: =IFERROR(BA13/AY13,"-") -> -0.24206349 | BC13: =AZ13*10000/J13 -> 47.04897 | BD13: =(MAX(BC$8:BC$63)-BC13)/MAX(BC$8:BC$63)*5 -> 3.2453489 | BE13: =_xlfn.RANK.EQ(BC13,BC$8:BC$63,0) -> 13 | BF13: =AK13*AK$4+AQ13*AQ$4+AX13*AX$4+BE13*BE$4 -> 22.9 | BH13: =O13*O$4+T13*T$4+AX$4*AX13+BE13*BE$4 -> 22.6 | BI13: =AX$3*AX13+BE$3*BE13 -> 20.5 | BJ13: =AW13*AX$3+BD13*BE$3 -> 3.6057095 | BK13: =_xlfn.RANK.EQ(BJ13,BJ$8:BJ$63,1) -> 18 | BL13: =AT13/J13*10000 -> 1.4779781 | BM13: =_xlfn.RANK.EQ(BL13,BL$8:BL$63,1) -> 25 | BN13: =BA13/J13*10000 -> -15.026111 | BO13: =_xlfn.RANK.EQ(BN13,BN$8:BN$63,1) -> 11 | BP13: =BM13*BL$3+BO13*BN$3 -> 18
D14: Люберцы | I14: 12 | J14: 414189 | K14: 4 | L14: 0 | M14: -4 | N14: =IFERROR(M14/K14,"-") -> -1 | O14: =_xlfn.RANK.EQ(L14,L$8:L$63,0) -> 47 | P14: 6 | Q14: 2 | R14: =Q14-P14 -> -4 | S14: =IFERROR(R14/P14,"-") -> -0.66666667 | T14: =_xlfn.RANK.EQ(Q14,Q$8:Q$63,0) -> 31 | U14: 163 | V14: 133 | W14: =V14-U14 -> -30 | X14: =IFERROR(W14/U14,"-") -> -0.18404908 | Y14: =_xlfn.RANK.EQ(V14,V$8:V$63,0) -> 25 | Z14: 482 | AA14: 573 | AB14: =AA14-Z14 -> 91 | AC14: =IFERROR(AB14/Z14,"-") -> 0.18879668 | AD14: =_xlfn.RANK.EQ(AA14,AA$8:AA$63,0) -> 20 | AE14: =O14*O$4+T14*T$4+Y14*Y$4+AD14*AD$4 -> 27.45 | AF14: =K14 -> 4 | AG14: =L14 -> 0 | AH14: =AG14-AF14 -> -4 | AI14: =IFERROR(AH14/AF14,"-") -> -1 | AJ14: =10000*AG14/J14 -> 0 | AK14: =_xlfn.RANK.EQ(AJ14,AJ$8:AJ$63,0) -> 47 | AL14: =P14 -> 6 | AM14: =Q14 -> 2 | AN14: =AM14-AL14 -> -4 | AO14: =IFERROR(AN14/AL14,"-") -> -0.66666667 | AP14: =10000*AM14/J14 -> 0.048287135 | AQ14: =_xlfn.RANK.EQ(AP14,AP$8:AP$63,0) -> 36 | AR14: 163 | AS14: 133 | AT14: =AS14-AR14 -> -30 | AU14: =IFERROR(AT14/AR14,"-") -> -0.18404908 | AV14: =10000*AS14/J14 -> 3.2110945 | AW14: =(MAX(AV$8:AV$63)-AV14)/MAX(AV$8:AV$63)*5 -> 4.6256094 | AX14: =_xlfn.RANK.EQ(AV14,AV$8:AV$63,0) -> 48 | AY14: 482 | AZ14: 573 | BA14: =AZ14-AY14 -> 91 | BB14: =IFERROR(BA14/AY14,"-") -> 0.18879668 | BC14: =AZ14*10000/J14 -> 13.834264 | BD14: =(MAX(BC$8:BC$63)-BC14)/MAX(BC$8:BC$63)*5 -> 4.484063 | BE14: =_xlfn.RANK.EQ(BC14,BC$8:BC$63,0) -> 44 | BF14: =AK14*AK$4+AQ14*AQ$4+AX14*AX$4+BE14*BE$4 -> 44.65 | BH14: =O14*O$4+T14*T$4+AX$4*AX14+BE14*BE$4 -> 43.9 | BI14: =AX$3*AX14+BE$3*BE14 -> 46 | BJ14: =AW14*AX$3+BD14*BE$3 -> 4.5548362 | BK14: =_xlfn.RANK.EQ(BJ14,BJ$8:BJ$63,1) -> 46 | BL14: =AT14/J14*10000 -> -0.72430702 | BM14: =_xlfn.RANK.EQ(BL14,BL$8:BL$63,1) -> 7 | BN14: =BA14/J14*10000 -> 2.1970646 | BO14: =_xlfn.RANK.EQ(BN14,BN$8:BN$63,1) -> 38 | BP14: =BM14*BL$3+BO14*BN$3 -> 22.5
D15: Ленинский | I15: 11 | J15: 309204 | K15: 8 | L15: 4 | M15: -4 | N15: =IFERROR(M15/K15,"-") -> -0.5 | O15: =_xlfn.RANK.EQ(L15,L$8:L$63,0) -> 34 | P15: 7 | Q15: 0 | R15: =Q15-P15 -> -7 | S15: =IFERROR(R15/P15,"-") -> -1 | T15: =_xlfn.RANK.EQ(Q15,Q$8:Q$63,0) -> 38 | U15: 167 | V15: 192 | W15: =V15-U15 -> 25 | X15: =IFERROR(W15/U15,"-") -> 0.1497006 | Y15: =_xlfn.RANK.EQ(V15,V$8:V$63,0) -> 22 | Z15: 635 | AA15: 400 | AB15: =AA15-Z15 -> -235 | AC15: =IFERROR(AB15/Z15,"-") -> -0.37007874 | AD15: =_xlfn.RANK.EQ(AA15,AA$8:AA$63,0) -> 25 | AE15: =O15*O$4+T15*T$4+Y15*Y$4+AD15*AD$4 -> 27.25 | AF15: =K15 -> 8 | AG15: =L15 -> 4 | AH15: =AG15-AF15 -> -4 | AI15: =IFERROR(AH15/AF15,"-") -> -0.5 | AJ15: =10000*AG15/J15 -> 0.12936443 | AK15: =_xlfn.RANK.EQ(AJ15,AJ$8:AJ$63,0) -> 42 | AL15: =P15 -> 7 | AM15: =Q15 -> 0 | AN15: =AM15-AL15 -> -7 | AO15: =IFERROR(AN15/AL15,"-") -> -1 | AP15: =10000*AM15/J15 -> 0 | AQ15: =_xlfn.RANK.EQ(AP15,AP$8:AP$63,0) -> 38 | AR15: 167 | AS15: 192 | AT15: =AS15-AR15 -> 25 | AU15: =IFERROR(AT15/AR15,"-") -> 0.1497006 | AV15: =10000*AS15/J15 -> 6.2094928 | AW15: =(MAX(AV$8:AV$63)-AV15)/MAX(AV$8:AV$63)*5 -> 4.2760177 | AX15: =_xlfn.RANK.EQ(AV15,AV$8:AV$63,0) -> 39 | AY15: 635 | AZ15: 400 | BA15: =AZ15-AY15 -> -235 | BB15: =IFERROR(BA15/AY15,"-") -> -0.37007874 | BC15: =AZ15*10000/J15 -> 12.936443 | BD15: =(MAX(BC$8:BC$63)-BC15)/MAX(BC$8:BC$63)*5 -> 4.5175464 | BE15: =_xlfn.RANK.EQ(BC15,BC$8:BC$63,0) -> 46 | BF15: =AK15*AK$4+AQ15*AQ$4+AX15*AX$4+BE15*BE$4 -> 41.75 | BH15: =O15*O$4+T15*T$4+AX$4*AX15+BE15*BE$4 -> 40.55 | BI15: =AX$3*AX15+BE$3*BE15 -> 42.5 | BJ15: =AW15*AX$3+BD15*BE$3 -> 4.3967821 | BK15: =_xlfn.RANK.EQ(BJ15,BJ$8:BJ$63,1) -> 43 | BL15: =AT15/J15*10000 -> 0.8085277 | BM15: =_xlfn.RANK.EQ(BL15,BL$8:BL$63,1) -> 18 | BN15: =BA15/J15*10000 -> -7.6001604 | BO15: =_xlfn.RANK.EQ(BN15,BN$8:BN$63,1) -> 14 | BP15: =BM15*BL$3+BO15*BN$3 -> 16
D16: Домодедово | I16: 9 | J16: 222807 | K16: 16 | L16: 20 | M16: 4 | N16: =IFERROR(M16/K16,"-") -> 0.25 | O16: =_xlfn.RANK.EQ(L16,L$8:L$63,0) -> 18 | P16: 12 | Q16: 16 | R16: =Q16-P16 -> 4 | S16: =IFERROR(R16/P16,"-") -> 0.33333333 | T16: =_xlfn.RANK.EQ(Q16,Q$8:Q$63,0) -> 14 | U16: 239 | V16: 324 | W16: =V16-U16 -> 85 | X16: =IFERROR(W16/U16,"-") -> 0.35564854 | Y16: =_xlfn.RANK.EQ(V16,V$8:V$63,0) -> 8 | Z16: 2294 | AA16: 1299 | AB16: =AA16-Z16 -> -995 | AC16: =IFERROR(AB16/Z16,"-") -> -0.43374019 | AD16: =_xlfn.RANK.EQ(AA16,AA$8:AA$63,0) -> 7 | AE16: =O16*O$4+T16*T$4+Y16*Y$4+AD16*AD$4 -> 10.05 | AF16: =K16 -> 16 | AG16: =L16 -> 20 | AH16: =AG16-AF16 -> 4 | AI16: =IFERROR(AH16/AF16,"-") -> 0.25 | AJ16: =10000*AG16/J16 -> 0.89763787 | AK16: =_xlfn.RANK.EQ(AJ16,AJ$8:AJ$63,0) -> 21 | AL16: =P16 -> 12 | AM16: =Q16 -> 16 | AN16: =AM16-AL16 -> 4 | AO16: =IFERROR(AN16/AL16,"-") -> 0.33333333 | AP16: =10000*AM16/J16 -> 0.71811029 | AQ16: =_xlfn.RANK.EQ(AP16,AP$8:AP$63,0) -> 18 | AR16: 239 | AS16: 324 | AT16: =AS16-AR16 -> 85 | AU16: =IFERROR(AT16/AR16,"-") -> 0.35564854 | AV16: =10000*AS16/J16 -> 14.541733 | AW16: =(MAX(AV$8:AV$63)-AV16)/MAX(AV$8:AV$63)*5 -> 3.3045383 | AX16: =_xlfn.RANK.EQ(AV16,AV$8:AV$63,0) -> 13 | AY16: 2294 | AZ16: 1299 | BA16: =AZ16-AY16 -> -995 | BB16: =IFERROR(BA16/AY16,"-") -> -0.43374019 | BC16: =AZ16*10000/J16 -> 58.301579 | BD16: =(MAX(BC$8:BC$63)-BC16)/MAX(BC$8:BC$63)*5 -> 2.8256925 | BE16: =_xlfn.RANK.EQ(BC16,BC$8:BC$63,0) -> 9 | BF16: =AK16*AK$4+AQ16*AQ$4+AX16*AX$4+BE16*BE$4 -> 13.55 | BH16: =O16*O$4+T16*T$4+AX$4*AX16+BE16*BE$4 -> 12.5 | BI16: =AX$3*AX16+BE$3*BE16 -> 11 | BJ16: =AW16*AX$3+BD16*BE$3 -> 3.0651154 | BK16: =_xlfn.RANK.EQ(BJ16,BJ$8:BJ$63,1) -> 12 | BL16: =AT16/J16*10000 -> 3.8149609 | BM16: =_xlfn.RANK.EQ(BL16,BL$8:BL$63,1) -> 36 | BN16: =BA16/J16*10000 -> -44.657484 | BO16: =_xlfn.RANK.EQ(BN16,BN$8:BN$63,1) -> 5 | BP16: =BM16*BL$3+BO16*BN$3 -> 20.5
D17: Подольск | I17: 6 | J17: 350268 | K17: 27 | L17: 22 | M17: -5 | N17: =IFERROR(M17/K17,"-") -> -0.18518519 | O17: =_xlfn.RANK.EQ(L17,L$8:L$63,0) -> 16 | P17: 12 | Q17: 19 | R17: =Q17-P17 -> 7 | S17: =IFERROR(R17/P17,"-") -> 0.58333333 | T17: =_xlfn.RANK.EQ(Q17,Q$8:Q$63,0) -> 10 | U17: 481 | V17: 460 | W17: =V17-U17 -> -21 | X17: =IFERROR(W17/U17,"-") -> -0.043659044 | Y17: =_xlfn.RANK.EQ(V17,V$8:V$63,0) -> 5 | Z17: 1824 | AA17: 907 | AB17: =AA17-Z17 -> -917 | AC17: =IFERROR(AB17/Z17,"-") -> -0.50274123 | AD17: =_xlfn.RANK.EQ(AA17,AA$8:AA$63,0) -> 12 | AE17: =O17*O$4+T17*T$4+Y17*Y$4+AD17*AD$4 -> 9.85 | AF17: =K17 -> 27 | AG17: =L17 -> 22 | AH17: =AG17-AF17 -> -5 | AI17: =IFERROR(AH17/AF17,"-") -> -0.18518519 | AJ17: =10000*AG17/J17 -> 0.62809049 | AK17: =_xlfn.RANK.EQ(AJ17,AJ$8:AJ$63,0) -> 28 | AL17: =P17 -> 12 | AM17: =Q17 -> 19 | AN17: =AM17-AL17 -> 7 | AO17: =IFERROR(AN17/AL17,"-") -> 0.58333333 | AP17: =10000*AM17/J17 -> 0.54244179 | AQ17: =_xlfn.RANK.EQ(AP17,AP$8:AP$63,0) -> 21 | AR17: 481 | AS17: 460 | AT17: =AS17-AR17 -> -21 | AU17: =IFERROR(AT17/AR17,"-") -> -0.043659044 | AV17: =10000*AS17/J17 -> 13.132801 | AW17: =(MAX(AV$8:AV$63)-AV17)/MAX(AV$8:AV$63)*5 -> 3.4688097 | AX17: =_xlfn.RANK.EQ(AV17,AV$8:AV$63,0) -> 15 | AY17: 1824 | AZ17: 907 | BA17: =AZ17-AY17 -> -917 | BB17: =IFERROR(BA17/AY17,"-") -> -0.50274123 | BC17: =AZ17*10000/J17 -> 25.894458 | BD17: =(MAX(BC$8:BC$63)-BC17)/MAX(BC$8:BC$63)*5 -> 4.0342883 | BE17: =_xlfn.RANK.EQ(BC17,BC$8:BC$63,0) -> 26 | BF17: =AK17*AK$4+AQ17*AQ$4+AX17*AX$4+BE17*BE$4 -> 21.7 | BH17: =O17*O$4+T17*T$4+AX$4*AX17+BE17*BE$4 -> 18.25 | BI17: =AX$3*AX17+BE$3*BE17 -> 20.5 | BJ17: =AW17*AX$3+BD17*BE$3 -> 3.751549 | BK17: =_xlfn.RANK.EQ(BJ17,BJ$8:BJ$63,1) -> 24 | BL17: =AT17/J17*10000 -> -0.59954092 | BM17: =_xlfn.RANK.EQ(BL17,BL$8:BL$63,1) -> 8 | BN17: =BA17/J17*10000 -> -26.179954 | BO17: =_xlfn.RANK.EQ(BN17,BN$8:BN$63,1) -> 8 | BP17: =BM17*BL$3+BO17*BN$3 -> 8
D18: Серпухов | I18: 2 | J18: 237574 | K18: 19 | L18: 15 | M18: -4 | N18: =IFERROR(M18/K18,"-") -> -0.21052632 | O18: =_xlfn.RANK.EQ(L18,L$8:L$63,0) -> 20 | P18: 1 | Q18: 31 | R18: =Q18-P18 -> 30 | S18: =IFERROR(R18/P18,"-") -> 30 | T18: =_xlfn.RANK.EQ(Q18,Q$8:Q$63,0) -> 6 | U18: 210 | V18: 179 | W18: =V18-U18 -> -31 | X18: =IFERROR(W18/U18,"-") -> -0.14761905 | Y18: =_xlfn.RANK.EQ(V18,V$8:V$63,0) -> 23 | Z18: 583 | AA18: 456 | AB18: =AA18-Z18 -> -127 | AC18: =IFERROR(AB18/Z18,"-") -> -0.21783876 | AD18: =_xlfn.RANK.EQ(AA18,AA$8:AA$63,0) -> 23 | AE18: =O18*O$4+T18*T$4+Y18*Y$4+AD18*AD$4 -> 20 | AF18: =K18 -> 19 | AG18: =L18 -> 15 | AH18: =AG18-AF18 -> -4 | AI18: =IFERROR(AH18/AF18,"-") -> -0.21052632 | AJ18: =10000*AG18/J18 -> 0.63138222 | AK18: =_xlfn.RANK.EQ(AJ18,AJ$8:AJ$63,0) -> 27 | AL18: =P18 -> 1 | AM18: =Q18 -> 31 | AN18: =AM18-AL18 -> 30 | AO18: =IFERROR(AN18/AL18,"-") -> 30 | AP18: =10000*AM18/J18 -> 1.3048566 | AQ18: =_xlfn.RANK.EQ(AP18,AP$8:AP$63,0) -> 10 | AR18: 210 | AS18: 179 | AT18: =AS18-AR18 -> -31 | AU18: =IFERROR(AT18/AR18,"-") -> -0.14761905 | AV18: =10000*AS18/J18 -> 7.5344945 | AW18: =(MAX(AV$8:AV$63)-AV18)/MAX(AV$8:AV$63)*5 -> 4.121532 | AX18: =_xlfn.RANK.EQ(AV18,AV$8:AV$63,0) -> 36 | AY18: 583 | AZ18: 456 | BA18: =AZ18-AY18 -> -127 | BB18: =IFERROR(BA18/AY18,"-") -> -0.21783876 | BC18: =AZ18*10000/J18 -> 19.19402 | BD18: =(MAX(BC$8:BC$63)-BC18)/MAX(BC$8:BC$63)*5 -> 4.2841755 | BE18: =_xlfn.RANK.EQ(BC18,BC$8:BC$63,0) -> 39 | BF18: =AK18*AK$4+AQ18*AQ$4+AX18*AX$4+BE18*BE$4 -> 31.8 | BH18: =O18*O$4+T18*T$4+AX$4*AX18+BE18*BE$4 -> 30.15 | BI18: =AX$3*AX18+BE$3*BE18 -> 37.5 | BJ18: =AW18*AX$3+BD18*BE$3 -> 4.2028538 | BK18: =_xlfn.RANK.EQ(BJ18,BJ$8:BJ$63,1) -> 39 | BL18: =AT18/J18*10000 -> -1.3048566 | BM18: =_xlfn.RANK.EQ(BL18,BL$8:BL$63,1) -> 4 | BN18: =BA18/J18*10000 -> -5.3457028 | BO18: =_xlfn.RANK.EQ(BN18,BN$8:BN$63,1) -> 18 | BP18: =BM18*BL$3+BO18*BN$3 -> 11
D19: Ступино | I19: 1 | J19: 118268 | K19: 14 | L19: 23 | M19: 9 | N19: =IFERROR(M19/K19,"-") -> 0.64285714 | O19: =_xlfn.RANK.EQ(L19,L$8:L$63,0) -> 14 | P19: 12 | Q19: 22 | R19: =Q19-P19 -> 10 | S19: =IFERROR(R19/P19,"-") -> 0.83333333 | T19: =_xlfn.RANK.EQ(Q19,Q$8:Q$63,0) -> 9 | U19: 196 | V19: 312 | W19: =V19-U19 -> 116 | X19: =IFERROR(W19/U19,"-") -> 0.59183673 | Y19: =_xlfn.RANK.EQ(V19,V$8:V$63,0) -> 10 | Z19: 2437 | AA19: 1384 | AB19: =AA19-Z19 -> -1053 | AC19: =IFERROR(AB19/Z19,"-") -> -0.43208863 | AD19: =_xlfn.RANK.EQ(AA19,AA$8:AA$63,0) -> 5 | AE19: =O19*O$4+T19*T$4+Y19*Y$4+AD19*AD$4 -> 8.7 | AF19: =K19 -> 14 | AG19: =L19 -> 23 | AH19: =AG19-AF19 -> 9 | AI19: =IFERROR(AH19/AF19,"-") -> 0.64285714 | AJ19: =10000*AG19/J19 -> 1.9447357 | AK19: =_xlfn.RANK.EQ(AJ19,AJ$8:AJ$63,0) -> 5 | AL19: =P19 -> 12 | AM19: =Q19 -> 22 | AN19: =AM19-AL19 -> 10 | AO19: =IFERROR(AN19/AL19,"-") -> 0.83333333 | AP19: =10000*AM19/J19 -> 1.860182 | AQ19: =_xlfn.RANK.EQ(AP19,AP$8:AP$63,0) -> 7 | AR19: 196 | AS19: 312 | AT19: =AS19-AR19 -> 116 | AU19: =IFERROR(AT19/AR19,"-") -> 0.59183673 | AV19: =10000*AS19/J19 -> 26.380762 | AW19: =(MAX(AV$8:AV$63)-AV19)/MAX(AV$8:AV$63)*5 -> 1.9241925 | AX19: =_xlfn.RANK.EQ(AV19,AV$8:AV$63,0) -> 4 | AY19: 2437 | AZ19: 1384 | BA19: =AZ19-AY19 -> -1053 | BB19: =IFERROR(BA19/AY19,"-") -> -0.43208863 | BC19: =AZ19*10000/J19 -> 117.02236 | BD19: =(MAX(BC$8:BC$63)-BC19)/MAX(BC$8:BC$63)*5 -> 0.63575136 | BE19: =_xlfn.RANK.EQ(BC19,BC$8:BC$63,0) -> 3 | BF19: =AK19*AK$4+AQ19*AQ$4+AX19*AX$4+BE19*BE$4 -> 4.25 | BH19: =O19*O$4+T19*T$4+AX$4*AX19+BE19*BE$4 -> 5.9 | BI19: =AX$3*AX19+BE$3*BE19 -> 3.5 | BJ19: =AW19*AX$3+BD19*BE$3 -> 1.2799719 | BK19: =_xlfn.RANK.EQ(BJ19,BJ$8:BJ$63,1) -> 2 | BL19: =AT19/J19*10000 -> 9.8082322 | BM19: =_xlfn.RANK.EQ(BL19,BL$8:BL$63,1) -> 51 | BN19: =BA19/J19*10000 -> -89.035073 | BO19: =_xlfn.RANK.EQ(BN19,BN$8:BN$63,1) -> 2 | BP19: =BM19*BL$3+BO19*BN$3 -> 26.5
D20: Чехов | I20: 3 | J20: 146908 | K20: 18 | L20: 58 | M20: 40 | N20: =IFERROR(M20/K20,"-") -> 2.2222222 | O20: =_xlfn.RANK.EQ(L20,L$8:L$63,0) -> 1 | P20: 20 | Q20: 87 | R20: =Q20-P20 -> 67 | S20: =IFERROR(R20/P20,"-") -> 3.35 | T20: =_xlfn.RANK.EQ(Q20,Q$8:Q$63,0) -> 2 | U20: 239 | V20: 313 | W20: =V20-U20 -> 74 | X20: =IFERROR(W20/U20,"-") -> 0.30962343 | Y20: =_xlfn.RANK.EQ(V20,V$8:V$63,0) -> 9 | Z20: 2706 | AA20: 1216 | AB20: =AA20-Z20 -> -1490 | AC20: =IFERROR(AB20/Z20,"-") -> -0.55062823 | AD20: =_xlfn.RANK.EQ(AA20,AA$8:AA$63,0) -> 8 | AE20: =O20*O$4+T20*T$4+Y20*Y$4+AD20*AD$4 -> 6.4 | AF20: =K20 -> 18 | AG20: =L20 -> 58 | AH20: =AG20-AF20 -> 40 | AI20: =IFERROR(AH20/AF20,"-") -> 2.2222222 | AJ20: =10000*AG20/J20 -> 3.9480491 | AK20: =_xlfn.RANK.EQ(AJ20,AJ$8:AJ$63,0) -> 2 | AL20: =P20 -> 20 | AM20: =Q20 -> 87 | AN20: =AM20-AL20 -> 67 | AO20: =IFERROR(AN20/AL20,"-") -> 3.35 | AP20: =10000*AM20/J20 -> 5.9220737 | AQ20: =_xlfn.RANK.EQ(AP20,AP$8:AP$63,0) -> 2 | AR20: 239 | AS20: 313 | AT20: =AS20-AR20 -> 74 | AU20: =IFERROR(AT20/AR20,"-") -> 0.30962343 | AV20: =10000*AS20/J20 -> 21.305851 | AW20: =(MAX(AV$8:AV$63)-AV20)/MAX(AV$8:AV$63)*5 -> 2.5158907 | AX20: =_xlfn.RANK.EQ(AV20,AV$8:AV$63,0) -> 6 | AY20: 2706 | AZ20: 1216 | BA20: =AZ20-AY20 -> -1490 | BB20: =IFERROR(BA20/AY20,"-") -> -0.55062823 | BC20: =AZ20*10000/J20 -> 82.772892 | BD20: =(MAX(BC$8:BC$63)-BC20)/MAX(BC$8:BC$63)*5 -> 1.9130558 | BE20: =_xlfn.RANK.EQ(BC20,BC$8:BC$63,0) -> 6 | BF20: =AK20*AK$4+AQ20*AQ$4+AX20*AX$4+BE20*BE$4 -> 4.8 | BH20: =O20*O$4+T20*T$4+AX$4*AX20+BE20*BE$4 -> 4.65 | BI20: =AX$3*AX20+BE$3*BE20 -> 6 | BJ20: =AW20*AX$3+BD20*BE$3 -> 2.2144733 | BK20: =_xlfn.RANK.EQ(BJ20,BJ$8:BJ$63,1) -> 5 | BL20: =AT20/J20*10000 -> 5.0371661 | BM20: =_xlfn.RANK.EQ(BL20,BL$8:BL$63,1) -> 40 | BN20: =BA20/J20*10000 -> -101.42402 | BO20: =_xlfn.RANK.EQ(BN20,BN$8:BN$63,1) -> 1 | BP20: =BM20*BL$3+BO20*BN$3 -> 20.5
... D34: Дмитров | I34: 6 | J34: 164318 | K34: 29 | L34: 29 | M34: 0 | N34: =IFERROR(M34/K34,"-") -> 0 | O34: =_xlfn.RANK.EQ(L34,L$8:L$63,0) -> 8 | P34: 12 | Q34: 53 | R34: =Q34-P34 -> 41 | S34: =IFERROR(R34/P34,"-") -> 3.4166667 | T34: =_xlfn.RANK.EQ(Q34,Q$8:Q$63,0) -> 4 | U34: 44 | V34: 220 | W34: =V34-U34 -> 176 | X34: =IFERROR(W34/U34,"-") -> 4 | Y34: =_xlfn.RANK.EQ(V34,V$8:V$63,0) -> 18 | Z34: 962 | AA34: 2203 | AB34: =AA34-Z34 -> 1241 | AC34: =IFERROR(AB34/Z34,"-") -> 1.2900208 | AD34: =_xlfn.RANK.EQ(AA34,AA$8:AA$63,0) -> 2 | AE34: =O34*O$4+T34*T$4+Y34*Y$4+AD34*AD$4 -> 8.8 | AF34: =K34 -> 29 | AG34: =L34 -> 29 | AH34: =AG34-AF34 -> 0 | AI34: =IFERROR(AH34/AF34,"-") -> 0 | AJ34: =10000*AG34/J34 -> 1.7648706 | AK34: =_xlfn.RANK.EQ(AJ34,AJ$8:AJ$63,0) -> 9 | AL34: =P34 -> 12 | AM34: =Q34 -> 53 | AN34: =AM34-AL34 -> 41 | AO34: =IFERROR(AN34/AL34,"-") -> 3.4166667 | AP34: =10000*AM34/J34 -> 3.2254531 | AQ34: =_xlfn.RANK.EQ(AP34,AP$8:AP$63,0) -> 4 | AR34: 44 | AS34: 220 | AT34: =AS34-AR34 -> 176 | AU34: =IFERROR(AT34/AR34,"-") -> 4 | AV34: =10000*AS34/J34 -> 13.388673 | AW34: =(MAX(AV$8:AV$63)-AV34)/MAX(AV$8:AV$63)*5 -> 3.4389768 | AX34: =_xlfn.RANK.EQ(AV34,AV$8:AV$63,0) -> 14 | AY34: 962 | AZ34: 2203 | BA34: =AZ34-AY34 -> 1241 | BB34: =IFERROR(BA34/AY34,"-") -> 1.2900208 | BC34: =AZ34*10000/J34 -> 134.0693 | BD34: =(MAX(BC$8:BC$63)-BC34)/MAX(BC$8:BC$63)*5 -> 0 | BE34: =_xlfn.RANK.EQ(BC34,BC$8:BC$63,0) -> 1 | BF34: =AK34*AK$4+AQ34*AQ$4+AX34*AX$4+BE34*BE$4 -> 7.2 | BH34: =O34*O$4+T34*T$4+AX$4*AX34+BE34*BE$4 -> 7.05 | BI34: =AX$3*AX34+BE$3*BE34 -> 7.5 | BJ34: =AW34*AX$3+BD34*BE$3 -> 1.7194884 | BK34: =_xlfn.RANK.EQ(BJ34,BJ$8:BJ$63,1) -> 4 | BL34: =AT34/J34*10000 -> 10.710939 | BM34: =_xlfn.RANK.EQ(BL34,BL$8:BL$63,1) -> 54 | BN34: =BA34/J34*10000 -> 75.524288 | BO34: =_xlfn.RANK.EQ(BN34,BN$8:BN$63,1) -> 56 | BP34: =BM34*BL$3+BO34*BN$3 -> 55
D35: Волоколамск | J35: 65122 | K35: 14 | L35: 10 | M35: -4 | N35: =IFERROR(M35/K35,"-") -> -0.28571429 | O35: =_xlfn.RANK.EQ(L35,L$8:L$63,0) -> 24 | P35: 6 | Q35: 4 | R35: =Q35-P35 -> -2 | S35: =IFERROR(R35/P35,"-") -> -0.33333333 | T35: =_xlfn.RANK.EQ(Q35,Q$8:Q$63,0) -> 28 | U35: 45 | V35: 79 | W35: =V35-U35 -> 34 | X35: =IFERROR(W35/U35,"-") -> 0.75555556 | Y35: =_xlfn.RANK.EQ(V35,V$8:V$63,0) -> 35 | Z35: 180 | AA35: 241 | AB35: =AA35-Z35 -> 61 | AC35: =IFERROR(AB35/Z35,"-") -> 0.33888889 | AD35: =_xlfn.RANK.EQ(AA35,AA$8:AA$63,0) -> 34 | AE35: =O35*O$4+T35*T$4+Y35*Y$4+AD35*AD$4 -> 31.95 | AF35: =K35 -> 14 | AG35: =L35 -> 10 | AH35: =AG35-AF35 -> -4 | AI35: =IFERROR(AH35/AF35,"-") -> -0.28571429 | AJ35: =10000*AG35/J35 -> 1.5355794 | AK35: =_xlfn.RANK.EQ(AJ35,AJ$8:AJ$63,0) -> 11 | AL35: =P35 -> 6 | AM35: =Q35 -> 4 | AN35: =AM35-AL35 -> -2 | AO35: =IFERROR(AN35/AL35,"-") -> -0.33333333 | AP35: =10000*AM35/J35 -> 0.61423175 | AQ35: =_xlfn.RANK.EQ(AP35,AP$8:AP$63,0) -> 20 | AR35: 45 | AS35: 79 | AT35: =AS35-AR35 -> 34 | AU35: =IFERROR(AT35/AR35,"-") -> 0.75555556 | AV35: =10000*AS35/J35 -> 12.131077 | AW35: =(MAX(AV$8:AV$63)-AV35)/MAX(AV$8:AV$63)*5 -> 3.5856035 | AX35: =_xlfn.RANK.EQ(AV35,AV$8:AV$63,0) -> 17 | AY35: 180 | AZ35: 241 | BA35: =AZ35-AY35 -> 61 | BB35: =IFERROR(BA35/AY35,"-") -> 0.33888889 | BC35: =AZ35*10000/J35 -> 37.007463 | BD35: =(MAX(BC$8:BC$63)-BC35)/MAX(BC$8:BC$63)*5 -> 3.6198383 | BE35: =_xlfn.RANK.EQ(BC35,BC$8:BC$63,0) -> 17 | BF35: =AK35*AK$4+AQ35*AQ$4+AX35*AX$4+BE35*BE$4 -> 16.55 | BH35: =O35*O$4+T35*T$4+AX$4*AX35+BE35*BE$4 -> 19.7 | BI35: =AX$3*AX35+BE$3*BE35 -> 17 | BJ35: =AW35*AX$3+BD35*BE$3 -> 3.6027209 | BK35: =_xlfn.RANK.EQ(BJ35,BJ$8:BJ$63,1) -> 17 | BL35: =AT35/J35*10000 -> 5.2209699 | BM35: =_xlfn.RANK.EQ(BL35,BL$8:BL$63,1) -> 44 | BN35: =BA35/J35*10000 -> 9.3670342 | BO35: =_xlfn.RANK.EQ(BN35,BN$8:BN$63,1) -> 48 | BP35: =BM35*BL$3+BO35*BN$3 -> 46
D36: Воскресенск | J36: 160613 | K36: 32 | L36: 28 | M36: -4 | N36: =IFERROR(M36/K36,"-") -> -0.125 | O36: =_xlfn.RANK.EQ(L36,L$8:L$63,0) -> 12 | P36: 15 | Q36: 6 | R36: =Q36-P36 -> -9 | S36: =IFERROR(R36/P36,"-") -> -0.6 | T36: =_xlfn.RANK.EQ(Q36,Q$8:Q$63,0) -> 23 | U36: 128 | V36: 242 | W36: =V36-U36 -> 114 | X36: =IFERROR(W36/U36,"-") -> 0.890625 | Y36: =_xlfn.RANK.EQ(V36,V$8:V$63,0) -> 16 | Z36: 638 | AA36: 688 | AB36: =AA36-Z36 -> 50 | AC36: =IFERROR(AB36/Z36,"-") -> 0.078369906 | AD36: =_xlfn.RANK.EQ(AA36,AA$8:AA$63,0) -> 16 | AE36: =O36*O$4+T36*T$4+Y36*Y$4+AD36*AD$4 -> 16.45 | AF36: =K36 -> 32 | AG36: =L36 -> 28 | AH36: =AG36-AF36 -> -4 | AI36: =IFERROR(AH36/AF36,"-") -> -0.125 | AJ36: =10000*AG36/J36 -> 1.7433209 | AK36: =_xlfn.RANK.EQ(AJ36,AJ$8:AJ$63,0) -> 10 | AL36: =P36 -> 15 | AM36: =Q36 -> 6 | AN36: =AM36-AL36 -> -9 | AO36: =IFERROR(AN36/AL36,"-") -> -0.6 | AP36: =10000*AM36/J36 -> 0.37356876 | AQ36: =_xlfn.RANK.EQ(AP36,AP$8:AP$63,0) -> 24 | AR36: 128 | AS36: 242 | AT36: =AS36-AR36 -> 114 | AU36: =IFERROR(AT36/AR36,"-") -> 0.890625 | AV36: =10000*AS36/J36 -> 15.067274 | AW36: =(MAX(AV$8:AV$63)-AV36)/MAX(AV$8:AV$63)*5 -> 3.2432641 | AX36: =_xlfn.RANK.EQ(AV36,AV$8:AV$63,0) -> 11 | AY36: 638 | AZ36: 688 | BA36: =AZ36-AY36 -> 50 | BB36: =IFERROR(BA36/AY36,"-") -> 0.078369906 | BC36: =AZ36*10000/J36 -> 42.835885 | BD36: =(MAX(BC$8:BC$63)-BC36)/MAX(BC$8:BC$63)*5 -> 3.4024723 | BE36: =_xlfn.RANK.EQ(BC36,BC$8:BC$63,0) -> 14 | BF36: =AK36*AK$4+AQ36*AQ$4+AX36*AX$4+BE36*BE$4 -> 13.85 | BH36: =O36*O$4+T36*T$4+AX$4*AX36+BE36*BE$4 -> 14 | BI36: =AX$3*AX36+BE$3*BE36 -> 12.5 | BJ36: =AW36*AX$3+BD36*BE$3 -> 3.3228682 | BK36: =_xlfn.RANK.EQ(BJ36,BJ$8:BJ$63,1) -> 15 | BL36: =AT36/J36*10000 -> 7.0978065 | BM36: =_xlfn.RANK.EQ(BL36,BL$8:BL$63,1) -> 49 | BN36: =BA36/J36*10000 -> 3.113073 | BO36: =_xlfn.RANK.EQ(BN36,BN$8:BN$63,1) -> 42 | BP36: =BM36*BL$3+BO36*BN$3 -> 45.5
D37: Егорьевск | J37: 111398 | K37: 15 | L37: 9 | M37: -6 | N37: =IFERROR(M37/K37,"-") -> -0.4 | O37: =_xlfn.RANK.EQ(L37,L$8:L$63,0) -> 25 | P37: 6 | Q37: 0 | R37: =Q37-P37 -> -6 | S37: =IFERROR(R37/P37,"-") -> -1 | T37: =_xlfn.RANK.EQ(Q37,Q$8:Q$63,0) -> 38 | U37: 102 | V37: 101 | W37: =V37-U37 -> -1 | X37: =IFERROR(W37/U37,"-") -> -0.0098039216 | Y37: =_xlfn.RANK.EQ(V37,V$8:V$63,0) -> 32 | Z37: 494 | AA37: 274 | AB37: =AA37-Z37 -> -220 | AC37: =IFERROR(AB37/Z37,"-") -> -0.44534413 | AD37: =_xlfn.RANK.EQ(AA37,AA$8:AA$63,0) -> 32 | AE37: =O37*O$4+T37*T$4+Y37*Y$4+AD37*AD$4 -> 31.85 | AF37: =K37 -> 15 | AG37: =L37 -> 9 | AH37: =AG37-AF37 -> -6 | AI37: =IFERROR(AH37/AF37,"-") -> -0.4 | AJ37: =10000*AG37/J37 -> 0.80791397 | AK37: =_xlfn.RANK.EQ(AJ37,AJ$8:AJ$63,0) -> 24 | AL37: =P37 -> 6 | AM37: =Q37 -> 0 | AN37: =AM37-AL37 -> -6 | AO37: =IFERROR(AN37/AL37,"-") -> -1 | AP37: =10000*AM37/J37 -> 0 | AQ37: =_xlfn.RANK.EQ(AP37,AP$8:AP$63,0) -> 38 | AR37: 102 | AS37: 101 | AT37: =AS37-AR37 -> -1 | AU37: =IFERROR(AT37/AR37,"-") -> -0.0098039216 | AV37: =10000*AS37/J37 -> 9.0665901 | AW37: =(MAX(AV$8:AV$63)-AV37)/MAX(AV$8:AV$63)*5 -> 3.9429007 | AX37: =_xlfn.RANK.EQ(AV37,AV$8:AV$63,0) -> 26 | AY37: 494 | AZ37: 274 | BA37: =AZ37-AY37 -> -220 | BB37: =IFERROR(BA37/AY37,"-") -> -0.44534413 | BC37: =AZ37*10000/J37 -> 24.596492 | BD37: =(MAX(BC$8:BC$63)-BC37)/MAX(BC$8:BC$63)*5 -> 4.0826949 | BE37: =_xlfn.RANK.EQ(BC37,BC$8:BC$63,0) -> 28 | BF37: =AK37*AK$4+AQ37*AQ$4+AX37*AX$4+BE37*BE$4 -> 28.2 | BH37: =O37*O$4+T37*T$4+AX$4*AX37+BE37*BE$4 -> 28.35 | BI37: =AX$3*AX37+BE$3*BE37 -> 27 | BJ37: =AW37*AX$3+BD37*BE$3 -> 4.0127978 | BK37: =_xlfn.RANK.EQ(BJ37,BJ$8:BJ$63,1) -> 28 | BL37: =AT37/J37*10000 -> -0.089768218 | BM37: =_xlfn.RANK.EQ(BL37,BL$8:BL$63,1) -> 14 | BN37: =BA37/J37*10000 -> -19.749008 | BO37: =_xlfn.RANK.EQ(BN37,BN$8:BN$63,1) -> 10 | BP37: =BM37*BL$3+BO37*BN$3 -> 12
D38: Коломна | J38: 214925 | K38: 9 | L38: 12 | M38: 3 | N38: =IFERROR(M38/K38,"-") -> 0.33333333 | O38: =_xlfn.RANK.EQ(L38,L$8:L$63,0) -> 22 | P38: 12 | Q38: 1 | R38: =Q38-P38 -> -11 | S38: =IFERROR(R38/P38,"-") -> -0.91666667 | T38: =_xlfn.RANK.EQ(Q38,Q$8:Q$63,0) -> 36 | U38: 142 | V38: 171 | W38: =V38-U38 -> 29 | X38: =IFERROR(W38/U38,"-") -> 0.20422535 | Y38: =_xlfn.RANK.EQ(V38,V$8:V$63,0) -> 24 | Z38: 472 | AA38: 355 | AB38: =AA38-Z38 -> -117 | AC38: =IFERROR(AB38/Z38,"-") -> -0.24788136 | AD38: =_xlfn.RANK.EQ(AA38,AA$8:AA$63,0) -> 29 | AE38: =O38*O$4+T38*T$4+Y38*Y$4+AD38*AD$4 -> 27.25 | AF38: =K38 -> 9 | AG38: =L38 -> 12 | AH38: =AG38-AF38 -> 3 | AI38: =IFERROR(AH38/AF38,"-") -> 0.33333333 | AJ38: =10000*AG38/J38 -> 0.5583343 | AK38: =_xlfn.RANK.EQ(AJ38,AJ$8:AJ$63,0) -> 31 | AL38: =P38 -> 12 | AM38: =Q38 -> 1 | AN38: =AM38-AL38 -> -11 | AO38: =IFERROR(AN38/AL38,"-") -> -0.91666667 | AP38: =10000*AM38/J38 -> 0.046527859 | AQ38: =_xlfn.RANK.EQ(AP38,AP$8:AP$63,0) -> 37 | AR38: 142 | AS38: 171 | AT38: =AS38-AR38 -> 29 | AU38: =IFERROR(AT38/AR38,"-") -> 0.20422535 | AV38: =10000*AS38/J38 -> 7.9562638 | AW38: =(MAX(AV$8:AV$63)-AV38)/MAX(AV$8:AV$63)*5 -> 4.0723568 | AX38: =_xlfn.RANK.EQ(AV38,AV$8:AV$63,0) -> 33 | AY38: 472 | AZ38: 355 | BA38: =AZ38-AY38 -> -117 | BB38: =IFERROR(BA38/AY38,"-") -> -0.24788136 | BC38: =AZ38*10000/J38 -> 16.51739 | BD38: =(MAX(BC$8:BC$63)-BC38)/MAX(BC$8:BC$63)*5 -> 4.3839981 | BE38: =_xlfn.RANK.EQ(BC38,BC$8:BC$63,0) -> 40 | BF38: =AK38*AK$4+AQ38*AQ$4+AX38*AX$4+BE38*BE$4 -> 35.75 | BH38: =O38*O$4+T38*T$4+AX$4*AX38+BE38*BE$4 -> 34.25 | BI38: =AX$3*AX38+BE$3*BE38 -> 36.5 | BJ38: =AW38*AX$3+BD38*BE$3 -> 4.2281774 | BK38: =_xlfn.RANK.EQ(BJ38,BJ$8:BJ$63,1) -> 40 | BL38: =AT38/J38*10000 -> 1.3493079 | BM38: =_xlfn.RANK.EQ(BL38,BL$8:BL$63,1) -> 22 | BN38: =BA38/J38*10000 -> -5.4437595 | BO38: =_xlfn.RANK.EQ(BN38,BN$8:BN$63,1) -> 17 | BP38: =BM38*BL$3+BO38*BN$3 -> 19.5
D39: Лосино-Петровский | J39: 70669 | K39: 0 | L39: 0 | M39: 0 | N39: =IFERROR(M39/K39,"-") -> - | O39: =_xlfn.RANK.EQ(L39,L$8:L$63,0) -> 47 | P39: 0 | Q39: 2 | R39: =Q39-P39 -> 2 | S39: =IFERROR(R39/P39,"-") -> - | T39: =_xlfn.RANK.EQ(Q39,Q$8:Q$63,0) -> 31 | U39: 19 | V39: 55 | W39: =V39-U39 -> 36 | X39: =IFERROR(W39/U39,"-") -> 1.8947368 | Y39: =_xlfn.RANK.EQ(V39,V$8:V$63,0) -> 39 | Z39: 174 | AA39: 145 | AB39: =AA39-Z39 -> -29 | AC39: =IFERROR(AB39/Z39,"-") -> -0.16666667 | AD39: =_xlfn.RANK.EQ(AA39,AA$8:AA$63,0) -> 41 | AE39: =O39*O$4+T39*T$4+Y39*Y$4+AD39*AD$4 -> 39.7 | AF39: =K39 -> 0 | AG39: =L39 -> 0 | AH39: =AG39-AF39 -> 0 | AI39: =IFERROR(AH39/AF39,"-") -> - | AJ39: =10000*AG39/J39 -> 0 | AK39: =_xlfn.RANK.EQ(AJ39,AJ$8:AJ$63,0) -> 47 | AL39: =P39 -> 0 | AM39: =Q39 -> 2 | AN39: =AM39-AL39 -> 2 | AO39: =IFERROR(AN39/AL39,"-") -> - | AP39: =10000*AM39/J39 -> 0.28300952 | AQ39: =_xlfn.RANK.EQ(AP39,AP$8:AP$63,0) -> 29 | AR39: 19 | AS39: 55 | AT39: =AS39-AR39 -> 36 | AU39: =IFERROR(AT39/AR39,"-") -> 1.8947368 | AV39: =10000*AS39/J39 -> 7.7827619 | AW39: =(MAX(AV$8:AV$63)-AV39)/MAX(AV$8:AV$63)*5 -> 4.0925858 | AX39: =_xlfn.RANK.EQ(AV39,AV$8:AV$63,0) -> 34 | AY39: 174 | AZ39: 145 | BA39: =AZ39-AY39 -> -29 | BB39: =IFERROR(BA39/AY39,"-") -> -0.16666667 | BC39: =AZ39*10000/J39 -> 20.51819 | BD39: =(MAX(BC$8:BC$63)-BC39)/MAX(BC$8:BC$63)*5 -> 4.2347916 | BE39: =_xlfn.RANK.EQ(BC39,BC$8:BC$63,0) -> 36 | BF39: =AK39*AK$4+AQ39*AQ$4+AX39*AX$4+BE39*BE$4 -> 35.9 | BH39: =O39*O$4+T39*T$4+AX$4*AX39+BE39*BE$4 -> 36.2 | BI39: =AX$3*AX39+BE$3*BE39 -> 35 | BJ39: =AW39*AX$3+BD39*BE$3 -> 4.1636887 | BK39: =_xlfn.RANK.EQ(BJ39,BJ$8:BJ$63,1) -> 38 | BL39: =AT39/J39*10000 -> 5.0941714 | BM39: =_xlfn.RANK.EQ(BL39,BL$8:BL$63,1) -> 42 | BN39: =BA39/J39*10000 -> -4.1036381 | BO39: =_xlfn.RANK.EQ(BN39,BN$8:BN$63,1) -> 19 | BP39: =BM39*BL$3+BO39*BN$3 -> 30.5
D40: Луховицы | J40: 60722 | K40: 4 | L40: 7 | M40: 3 | N40: =IFERROR(M40/K40,"-") -> 0.75 | O40: =_xlfn.RANK.EQ(L40,L$8:L$63,0) -> 27 | P40: 3 | Q40: 2 | R40: =Q40-P40 -> -1 | S40: =IFERROR(R40/P40,"-") -> -0.33333333 | T40: =_xlfn.RANK.EQ(Q40,Q$8:Q$63,0) -> 31 | U40: 83 | V40: 116 | W40: =V40-U40 -> 33 | X40: =IFERROR(W40/U40,"-") -> 0.39759036 | Y40: =_xlfn.RANK.EQ(V40,V$8:V$63,0) -> 29 | Z40: 270 | AA40: 194 | AB40: =AA40-Z40 -> -76 | AC40: =IFERROR(AB40/Z40,"-") -> -0.28148148 | AD40: =_xlfn.RANK.EQ(AA40,AA$8:AA$63,0) -> 38 | AE40: =O40*O$4+T40*T$4+Y40*Y$4+AD40*AD$4 -> 32.15 | AF40: =K40 -> 4 | AG40: =L40 -> 7 | AH40: =AG40-AF40 -> 3 | AI40: =IFERROR(AH40/AF40,"-") -> 0.75 | AJ40: =10000*AG40/J40 -> 1.1527947 | AK40: =_xlfn.RANK.EQ(AJ40,AJ$8:AJ$63,0) -> 15 | AL40: =P40 -> 3 | AM40: =Q40 -> 2 | AN40: =AM40-AL40 -> -1 | AO40: =IFERROR(AN40/AL40,"-") -> -0.33333333 | AP40: =10000*AM40/J40 -> 0.32936992 | AQ40: =_xlfn.RANK.EQ(AP40,AP$8:AP$63,0) -> 28 | AR40: 83 | AS40: 116 | AT40: =AS40-AR40 -> 33 | AU40: =IFERROR(AT40/AR40,"-") -> 0.39759036 | AV40: =10000*AS40/J40 -> 19.103455 | AW40: =(MAX(AV$8:AV$63)-AV40)/MAX(AV$8:AV$63)*5 -> 2.7726743 | AX40: =_xlfn.RANK.EQ(AV40,AV$8:AV$63,0) -> 8 | AY40: 270 | AZ40: 194 | BA40: =AZ40-AY40 -> -76 | BB40: =IFERROR(BA40/AY40,"-") -> -0.28148148 | BC40: =AZ40*10000/J40 -> 31.948882 | BD40: =(MAX(BC$8:BC$63)-BC40)/MAX(BC$8:BC$63)*5 -> 3.8084938 | BE40: =_xlfn.RANK.EQ(BC40,BC$8:BC$63,0) -> 24 | BF40: =AK40*AK$4+AQ40*AQ$4+AX40*AX$4+BE40*BE$4 -> 17.65 | BH40: =O40*O$4+T40*T$4+AX$4*AX40+BE40*BE$4 -> 19.9 | BI40: =AX$3*AX40+BE$3*BE40 -> 16 | BJ40: =AW40*AX$3+BD40*BE$3 -> 3.290584 | BK40: =_xlfn.RANK.EQ(BJ40,BJ$8:BJ$63,1) -> 14 | BL40: =AT40/J40*10000 -> 5.4346036 | BM40: =_xlfn.RANK.EQ(BL40,BL$8:BL$63,1) -> 45 | BN40: =BA40/J40*10000 -> -12.516057 | BO40: =_xlfn.RANK.EQ(BN40,BN$8:BN$63,1) -> 12 | BP40: =BM40*BL$3+BO40*BN$3 -> 28.5
D41: Можайск | J41: 92519 | K41: 17 | L41: 13 | M41: -4 | N41: =IFERROR(M41/K41,"-") -> -0.23529412 | O41: =_xlfn.RANK.EQ(L41,L$8:L$63,0) -> 21 | P41: 1 | Q41: 2 | R41: =Q41-P41 -> 1 | S41: =IFERROR(R41/P41,"-") -> 1 | T41: =_xlfn.RANK.EQ(Q41,Q$8:Q$63,0) -> 31 | U41: 42 | V41: 81 | W41: =V41-U41 -> 39 | X41: =IFERROR(W41/U41,"-") -> 0.92857143 | Y41: =_xlfn.RANK.EQ(V41,V$8:V$63,0) -> 34 | Z41: 245 | AA41: 208 | AB41: =AA41-Z41 -> -37 | AC41: =IFERROR(AB41/Z41,"-") -> -0.15102041 | AD41: =_xlfn.RANK.EQ(AA41,AA$8:AA$63,0) -> 37 | AE41: =O41*O$4+T41*T$4+Y41*Y$4+AD41*AD$4 -> 32.65 | AF41: =K41 -> 17 | AG41: =L41 -> 13 | AH41: =AG41-AF41 -> -4 | AI41: =IFERROR(AH41/AF41,"-") -> -0.23529412 | AJ41: =10000*AG41/J41 -> 1.4051168 | AK41: =_xlfn.RANK.EQ(AJ41,AJ$8:AJ$63,0) -> 13 | AL41: =P41 -> 1 | AM41: =Q41 -> 2 | AN41: =AM41-AL41 -> 1 | AO41: =IFERROR(AN41/AL41,"-") -> 1 | AP41: =10000*AM41/J41 -> 0.21617181 | AQ41: =_xlfn.RANK.EQ(AP41,AP$8:AP$63,0) -> 31 | AR41: 42 | AS41: 81 | AT41: =AS41-AR41 -> 39 | AU41: =IFERROR(AT41/AR41,"-") -> 0.92857143 | AV41: =10000*AS41/J41 -> 8.7549584 | AW41: =(MAX(AV$8:AV$63)-AV41)/MAX(AV$8:AV$63)*5 -> 3.9792347 | AX41: =_xlfn.RANK.EQ(AV41,AV$8:AV$63,0) -> 29 | AY41: 245 | AZ41: 208 | BA41: =AZ41-AY41 -> -37 | BB41: =IFERROR(BA41/AY41,"-") -> -0.15102041 | BC41: =AZ41*10000/J41 -> 22.481869 | BD41: =(MAX(BC$8:BC$63)-BC41)/MAX(BC$8:BC$63)*5 -> 4.1615579 | BE41: =_xlfn.RANK.EQ(BC41,BC$8:BC$63,0) -> 34 | BF41: =AK41*AK$4+AQ41*AQ$4+AX41*AX$4+BE41*BE$4 -> 28.65 | BH41: =O41*O$4+T41*T$4+AX$4*AX41+BE41*BE$4 -> 29.85 | BI41: =AX$3*AX41+BE$3*BE41 -> 31.5 | BJ41: =AW41*AX$3+BD41*BE$3 -> 4.0703963 | BK41: =_xlfn.RANK.EQ(BJ41,BJ$8:BJ$63,1) -> 31 | BL41: =AT41/J41*10000 -> 4.2153504 | BM41: =_xlfn.RANK.EQ(BL41,BL$8:BL$63,1) -> 38 | BN41: =BA41/J41*10000 -> -3.9991785 | BO41: =_xlfn.RANK.EQ(BN41,BN$8:BN$63,1) -> 20 | BP41: =BM41*BL$3+BO41*BN$3 -> 29
D42: Мытищи | J42: 299964 | K42: 20 | L42: 23 | M42: 3 | N42: =IFERROR(M42/K42,"-") -> 0.15 | O42: =_xlfn.RANK.EQ(L42,L$8:L$63,0) -> 14 | P42: 12 | Q42: 26 | R42: =Q42-P42 -> 14 | S42: =IFERROR(R42/P42,"-") -> 1.1666667 | T42: =_xlfn.RANK.EQ(Q42,Q$8:Q$63,0) -> 7 | U42: 226 | V42: 252 | W42: =V42-U42 -> 26 | X42: =IFERROR(W42/U42,"-") -> 0.11504425 | Y42: =_xlfn.RANK.EQ(V42,V$8:V$63,0) -> 15 | Z42: 858 | AA42: 687 | AB42: =AA42-Z42 -> -171 | AC42: =IFERROR(AB42/Z42,"-") -> -0.1993007 | AD42: =_xlfn.RANK.EQ(AA42,AA$8:AA$63,0) -> 17 | AE42: =O42*O$4+T42*T$4+Y42*Y$4+AD42*AD$4 -> 14.35 | AF42: =K42 -> 20 | AG42: =L42 -> 23 | AH42: =AG42-AF42 -> 3 | AI42: =IFERROR(AH42/AF42,"-") -> 0.15 | AJ42: =10000*AG42/J42 -> 0.76675868 | AK42: =_xlfn.RANK.EQ(AJ42,AJ$8:AJ$63,0) -> 25 | AL42: =P42 -> 12 | AM42: =Q42 -> 26 | AN42: =AM42-AL42 -> 14 | AO42: =IFERROR(AN42/AL42,"-") -> 1.1666667 | AP42: =10000*AM42/J42 -> 0.86677068 | AQ42: =_xlfn.RANK.EQ(AP42,AP$8:AP$63,0) -> 15 | AR42: 226 | AS42: 252 | AT42: =AS42-AR42 -> 26 | AU42: =IFERROR(AT42/AR42,"-") -> 0.11504425 | AV42: =10000*AS42/J42 -> 8.4010081 | AW42: =(MAX(AV$8:AV$63)-AV42)/MAX(AV$8:AV$63)*5 -> 4.0205028 | AX42: =_xlfn.RANK.EQ(AV42,AV$8:AV$63,0) -> 32 | AY42: 858 | AZ42: 687 | BA42: =AZ42-AY42 -> -171 | BB42: =IFERROR(BA42/AY42,"-") -> -0.1993007 | BC42: =AZ42*10000/J42 -> 22.902748 | BD42: =(MAX(BC$8:BC$63)-BC42)/MAX(BC$8:BC$63)*5 -> 4.1458616 | BE42: =_xlfn.RANK.EQ(BC42,BC$8:BC$63,0) -> 32 | BF42: =AK42*AK$4+AQ42*AQ$4+AX42*AX$4+BE42*BE$4 -> 28.4 | BH42: =O42*O$4+T42*T$4+AX$4*AX42+BE42*BE$4 -> 25.55 | BI42: =AX$3*AX42+BE$3*BE42 -> 32 | BJ42: =AW42*AX$3+BD42*BE$3 -> 4.0831822 | BK42: =_xlfn.RANK.EQ(BJ42,BJ$8:BJ$63,1) -> 32 | BL42: =AT42/J42*10000 -> 0.86677068 | BM42: =_xlfn.RANK.EQ(BL42,BL$8:BL$63,1) -> 19 | BN42: =BA42/J42*10000 -> -5.7006841 | BO42: =_xlfn.RANK.EQ(BN42,BN$8:BN$63,1) -> 16 | BP42: =BM42*BL$3+BO42*BN$3 -> 17.5
D43: Наро-Фоминск | J43: 194589 | K43: 28 | L43: 29 | M43: 1 | N43: =IFERROR(M43/K43,"-") -> 0.035714286 | O43: =_xlfn.RANK.EQ(L43,L$8:L$63,0) -> 8 | P43: 9 | Q43: 16 | R43: =Q43-P43 -> 7 | S43: =IFERROR(R43/P43,"-") -> 0.77777778 | T43: =_xlfn.RANK.EQ(Q43,Q$8:Q$63,0) -> 14 | U43: 347 | V43: 424 | W43: =V43-U43 -> 77 | X43: =IFERROR(W43/U43,"-") -> 0.22190202 | Y43: =_xlfn.RANK.EQ(V43,V$8:V$63,0) -> 6 | Z43: 946 | AA43: 1098 | AB43: =AA43-Z43 -> 152 | AC43: =IFERROR(AB43/Z43,"-") -> 0.16067653 | AD43: =_xlfn.RANK.EQ(AA43,AA$8:AA$63,0) -> 10 | AE43: =O43*O$4+T43*T$4+Y43*Y$4+AD43*AD$4 -> 8.9 | AF43: =K43 -> 28 | AG43: =L43 -> 29 | AH43: =AG43-AF43 -> 1 | AI43: =IFERROR(AH43/AF43,"-") -> 0.035714286 | AJ43: =10000*AG43/J43 -> 1.4903206 | AK43: =_xlfn.RANK.EQ(AJ43,AJ$8:AJ$63,0) -> 12 | AL43: =P43 -> 9 | AM43: =Q43 -> 16 | AN43: =AM43-AL43 -> 7 | AO43: =IFERROR(AN43/AL43,"-") -> 0.77777778 | AP43: =10000*AM43/J43 -> 0.82224586 | AQ43: =_xlfn.RANK.EQ(AP43,AP$8:AP$63,0) -> 16 | AR43: 347 | AS43: 424 | AT43: =AS43-AR43 -> 77 | AU43: =IFERROR(AT43/AR43,"-") -> 0.22190202 | AV43: =10000*AS43/J43 -> 21.789515 | AW43: =(MAX(AV$8:AV$63)-AV43)/MAX(AV$8:AV$63)*5 -> 2.459499 | AX43: =_xlfn.RANK.EQ(AV43,AV$8:AV$63,0) -> 5 | AY43: 946 | AZ43: 1098 | BA43: =AZ43-AY43 -> 152 | BB43: =IFERROR(BA43/AY43,"-") -> 0.16067653 | BC43: =AZ43*10000/J43 -> 56.426622 | BD43: =(MAX(BC$8:BC$63)-BC43)/MAX(BC$8:BC$63)*5 -> 2.8956174 | BE43: =_xlfn.RANK.EQ(BC43,BC$8:BC$63,0) -> 11 | BF43: =AK43*AK$4+AQ43*AQ$4+AX43*AX$4+BE43*BE$4 -> 9.8 | BH43: =O43*O$4+T43*T$4+AX$4*AX43+BE43*BE$4 -> 8.9 | BI43: =AX$3*AX43+BE$3*BE43 -> 8 | BJ43: =AW43*AX$3+BD43*BE$3 -> 2.6775582 | BK43: =_xlfn.RANK.EQ(BJ43,BJ$8:BJ$63,1) -> 9 | BL43: =AT43/J43*10000 -> 3.9570582 | BM43: =_xlfn.RANK.EQ(BL43,BL$8:BL$63,1) -> 37 | BN43: =BA43/J43*10000 -> 7.8113357 | BO43: =_xlfn.RANK.EQ(BN43,BN$8:BN$63,1) -> 46 | BP43: =BM43*BL$3+BO43*BN$3 -> 41.5
D44: Пушкино | J44: 300650 | K44: 25 | L44: 29 | M44: 4 | N44: =IFERROR(M44/K44,"-") -> 0.16 | O44: =_xlfn.RANK.EQ(L44,L$8:L$63,0) -> 8 | P44: 57 | Q44: 4 | R44: =Q44-P44 -> -53 | S44: =IFERROR(R44/P44,"-") -> -0.92982456 | T44: =_xlfn.RANK.EQ(Q44,Q$8:Q$63,0) -> 28 | U44: 318 | V44: 358 | W44: =V44-U44 -> 40 | X44: =IFERROR(W44/U44,"-") -> 0.12578616 | Y44: =_xlfn.RANK.EQ(V44,V$8:V$63,0) -> 7 | Z44: 1284 | AA44: 988 | AB44: =AA44-Z44 -> -296 | AC44: =IFERROR(AB44/Z44,"-") -> -0.2305296 | AD44: =_xlfn.RANK.EQ(AA44,AA$8:AA$63,0) -> 11 | AE44: =O44*O$4+T44*T$4+Y44*Y$4+AD44*AD$4 -> 11.7 | AF44: =K44 -> 25 | AG44: =L44 -> 29 | AH44: =AG44-AF44 -> 4 | AI44: =IFERROR(AH44/AF44,"-") -> 0.16 | AJ44: =10000*AG44/J44 -> 0.96457675 | AK44: =_xlfn.RANK.EQ(AJ44,AJ$8:AJ$63,0) -> 16 | AL44: =P44 -> 57 | AM44: =Q44 -> 4 | AN44: =AM44-AL44 -> -53 | AO44: =IFERROR(AN44/AL44,"-") -> -0.92982456 | AP44: =10000*AM44/J44 -> 0.13304507 | AQ44: =_xlfn.RANK.EQ(AP44,AP$8:AP$63,0) -> 33 | AR44: 318 | AS44: 358 | AT44: =AS44-AR44 -> 40 | AU44: =IFERROR(AT44/AR44,"-") -> 0.12578616 | AV44: =10000*AS44/J44 -> 11.907534 | AW44: =(MAX(AV$8:AV$63)-AV44)/MAX(AV$8:AV$63)*5 -> 3.6116671 | AX44: =_xlfn.RANK.EQ(AV44,AV$8:AV$63,0) -> 21 | AY44: 1284 | AZ44: 988 | BA44: =AZ44-AY44 -> -296 | BB44: =IFERROR(BA44/AY44,"-") -> -0.2305296 | BC44: =AZ44*10000/J44 -> 32.862132 | BD44: =(MAX(BC$8:BC$63)-BC44)/MAX(BC$8:BC$63)*5 -> 3.7744349 | BE44: =_xlfn.RANK.EQ(BC44,BC$8:BC$63,0) -> 22 | BF44: =AK44*AK$4+AQ44*AQ$4+AX44*AX$4+BE44*BE$4 -> 22.4 | BH44: =O44*O$4+T44*T$4+AX$4*AX44+BE44*BE$4 -> 20.45 | BI44: =AX$3*AX44+BE$3*BE44 -> 21.5 | BJ44: =AW44*AX$3+BD44*BE$3 -> 3.693051 | BK44: =_xlfn.RANK.EQ(BJ44,BJ$8:BJ$63,1) -> 21 | BL44: =AT44/J44*10000 -> 1.3304507 | BM44: =_xlfn.RANK.EQ(BL44,BL$8:BL$63,1) -> 21 | BN44: =BA44/J44*10000 -> -9.8453351 | BO44: =_xlfn.RANK.EQ(BN44,BN$8:BN$63,1) -> 13 | BP44: =BM44*BL$3+BO44*BN$3 -> 17
D45: Раменское | J45: 334391 | K45: 47 | L45: 31 | M45: -16 | N45: =IFERROR(M45/K45,"-") -> -0.34042553 | O45: =_xlfn.RANK.EQ(L45,L$8:L$63,0) -> 7 | P45: 53 | Q45: 71 | R45: =Q45-P45 -> 18 | S45: =IFERROR(R45/P45,"-") -> 0.33962264 | T45: =_xlfn.RANK.EQ(Q45,Q$8:Q$63,0) -> 3 | U45: 787 | V45: 709 | W45: =V45-U45 -> -78 | X45: =IFERROR(W45/U45,"-") -> -0.099110546 | Y45: =_xlfn.RANK.EQ(V45,V$8:V$63,0) -> 1 | Z45: 4445 | AA45: 2581 | AB45: =AA45-Z45 -> -1864 | AC45: =IFERROR(AB45/Z45,"-") -> -0.41934758 | AD45: =_xlfn.RANK.EQ(AA45,AA$8:AA$63,0) -> 1 | AE45: =O45*O$4+T45*T$4+Y45*Y$4+AD45*AD$4 -> 2.2 | AF45: =K45 -> 47 | AG45: =L45 -> 31 | AH45: =AG45-AF45 -> -16 | AI45: =IFERROR(AH45/AF45,"-") -> -0.34042553 | AJ45: =10000*AG45/J45 -> 0.92705844 | AK45: =_xlfn.RANK.EQ(AJ45,AJ$8:AJ$63,0) -> 17 | AL45: =P45 -> 53 | AM45: =Q45 -> 71 | AN45: =AM45-AL45 -> 18 | AO45: =IFERROR(AN45/AL45,"-") -> 0.33962264 | AP45: =10000*AM45/J45 -> 2.1232629 | AQ45: =_xlfn.RANK.EQ(AP45,AP$8:AP$63,0) -> 5 | AR45: 787 | AS45: 709 | AT45: =AS45-AR45 -> -78 | AU45: =IFERROR(AT45/AR45,"-") -> -0.099110546 | AV45: =10000*AS45/J45 -> 21.202724 | AW45: =(MAX(AV$8:AV$63)-AV45)/MAX(AV$8:AV$63)*5 -> 2.5279147 | AX45: =_xlfn.RANK.EQ(AV45,AV$8:AV$63,0) -> 7 | AY45: 4445 | AZ45: 2581 | BA45: =AZ45-AY45 -> -1864 | BB45: =IFERROR(BA45/AY45,"-") -> -0.41934758 | BC45: =AZ45*10000/J45 -> 77.185092 | BD45: =(MAX(BC$8:BC$63)-BC45)/MAX(BC$8:BC$63)*5 -> 2.121448 | BE45: =_xlfn.RANK.EQ(BC45,BC$8:BC$63,0) -> 7 | BF45: =AK45*AK$4+AQ45*AQ$4+AX45*AX$4+BE45*BE$4 -> 8.2 | BH45: =O45*O$4+T45*T$4+AX$4*AX45+BE45*BE$4 -> 6.4 | BI45: =AX$3*AX45+BE$3*BE45 -> 7 | BJ45: =AW45*AX$3+BD45*BE$3 -> 2.3246814 | BK45: =_xlfn.RANK.EQ(BJ45,BJ$8:BJ$63,1) -> 6 | BL45: =AT45/J45*10000 -> -2.3325987 | BM45: =_xlfn.RANK.EQ(BL45,BL$8:BL$63,1) -> 3 | BN45: =BA45/J45*10000 -> -55.743127 | BO45: =_xlfn.RANK.EQ(BN45,BN$8:BN$63,1) -> 3 | BP45: =BM45*BL$3+BO45*BN$3 -> 3
D46: Солнечногорск | J46: 133149 | K46: 45 | L46: 34 | M46: -11 | N46: =IFERROR(M46/K46,"-") -> -0.24444444 | O46: =_xlfn.RANK.EQ(L46,L$8:L$63,0) -> 4 | P46: 30 | Q46: 45 | R46: =Q46-P46 -> 15 | S46: =IFERROR(R46/P46,"-") -> 0.5 | T46: =_xlfn.RANK.EQ(Q46,Q$8:Q$63,0) -> 5 | U46: 432 | V46: 571 | W46: =V46-U46 -> 139 | X46: =IFERROR(W46/U46,"-") -> 0.32175926 | Y46: =_xlfn.RANK.EQ(V46,V$8:V$63,0) -> 3 | Z46: 2141 | AA46: 1703 | AB46: =AA46-Z46 -> -438 | AC46: =IFERROR(AB46/Z46,"-") -> -0.2045773 | AD46: =_xlfn.RANK.EQ(AA46,AA$8:AA$63,0) -> 3 | AE46: =O46*O$4+T46*T$4+Y46*Y$4+AD46*AD$4 -> 3.45 | AF46: =K46 -> 45 | AG46: =L46 -> 34 | AH46: =AG46-AF46 -> -11 | AI46: =IFERROR(AH46/AF46,"-") -> -0.24444444 | AJ46: =10000*AG46/J46 -> 2.5535303 | AK46: =_xlfn.RANK.EQ(AJ46,AJ$8:AJ$63,0) -> 4 | AL46: =P46 -> 30 | AM46: =Q46 -> 45 | AN46: =AM46-AL46 -> 15 | AO46: =IFERROR(AN46/AL46,"-") -> 0.5 | AP46: =10000*AM46/J46 -> 3.3796724 | AQ46: =_xlfn.RANK.EQ(AP46,AP$8:AP$63,0) -> 3 | AR46: 432 | AS46: 571 | AT46: =AS46-AR46 -> 139 | AU46: =IFERROR(AT46/AR46,"-") -> 0.32175926 | AV46: =10000*AS46/J46 -> 42.884288 | AW46: =(MAX(AV$8:AV$63)-AV46)/MAX(AV$8:AV$63)*5 -> 0 | AX46: =_xlfn.RANK.EQ(AV46,AV$8:AV$63,0) -> 1 | AY46: 2141 | AZ46: 1703 | BA46: =AZ46-AY46 -> -438 | BB46: =IFERROR(BA46/AY46,"-") -> -0.2045773 | BC46: =AZ46*10000/J46 -> 127.90182 | BD46: =(MAX(BC$8:BC$63)-BC46)/MAX(BC$8:BC$63)*5 -> 0.2300109 | BE46: =_xlfn.RANK.EQ(BC46,BC$8:BC$63,0) -> 2 | BF46: =AK46*AK$4+AQ46*AQ$4+AX46*AX$4+BE46*BE$4 -> 2.1 | BH46: =O46*O$4+T46*T$4+AX$4*AX46+BE46*BE$4 -> 2.4 | BI46: =AX$3*AX46+BE$3*BE46 -> 1.5 | BJ46: =AW46*AX$3+BD46*BE$3 -> 0.11500545 | BK46: =_xlfn.RANK.EQ(BJ46,BJ$8:BJ$63,1) -> 1 | BL46: =AT46/J46*10000 -> 10.439433 | BM46: =_xlfn.RANK.EQ(BL46,BL$8:BL$63,1) -> 53 | BN46: =BA46/J46*10000 -> -32.895478 | BO46: =_xlfn.RANK.EQ(BN46,BN$8:BN$63,1) -> 7 | BP46: =BM46*BL$3+BO46*BN$3 -> 30
... D60: Восход | J60: 2063 | K60: 0 | L60: 0 | M60: 0 | N60: =IFERROR(M60/K60,"-") -> - | O60: =_xlfn.RANK.EQ(L60,L$8:L$63,0) -> 47 | P60: 0 | Q60: 0 | R60: =Q60-P60 -> 0 | S60: =IFERROR(R60/P60,"-") -> - | T60: =_xlfn.RANK.EQ(Q60,Q$8:Q$63,0) -> 38 | U60: 0 | V60: 0 | W60: =V60-U60 -> 0 | X60: =IFERROR(W60/U60,"-") -> - | Y60: =_xlfn.RANK.EQ(V60,V$8:V$63,0) -> 54 | Z60: 0 | AA60: 0 | AB60: =AA60-Z60 -> 0 | AC60: =IFERROR(AB60/Z60,"-") -> - | AD60: =_xlfn.RANK.EQ(AA60,AA$8:AA$63,0) -> 56 | AE60: =O60*O$4+T60*T$4+Y60*Y$4+AD60*AD$4 -> 51.25 | AF60: =K60 -> 0 | AG60: =L60 -> 0 | AH60: =AG60-AF60 -> 0 | AI60: =IFERROR(AH60/AF60,"-") -> - | AJ60: =10000*AG60/J60 -> 0 | AK60: =_xlfn.RANK.EQ(AJ60,AJ$8:AJ$63,0) -> 47 | AL60: =P60 -> 0 | AM60: =Q60 -> 0 | AN60: =AM60-AL60 -> 0 | AO60: =IFERROR(AN60/AL60,"-") -> - | AP60: =10000*AM60/J60 -> 0 | AQ60: =_xlfn.RANK.EQ(AP60,AP$8:AP$63,0) -> 38 | AR60: 0 | AS60: 0 | AT60: =AS60-AR60 -> 0 | AU60: =IFERROR(AT60/AR60,"-") -> - | AV60: =10000*AS60/J60 -> 0 | AW60: =(MAX(AV$8:AV$63)-AV60)/MAX(AV$8:AV$63)*5 -> 5 | AX60: =_xlfn.RANK.EQ(AV60,AV$8:AV$63,0) -> 54 | AY60: 0 | AZ60: 0 | BA60: =AZ60-AY60 -> 0 | BB60: =IFERROR(BA60/AY60,"-") -> - | BC60: =AZ60*10000/J60 -> 0 | BD60: =(MAX(BC$8:BC$63)-BC60)/MAX(BC$8:BC$63)*5 -> 5 | BE60: =_xlfn.RANK.EQ(BC60,BC$8:BC$63,0) -> 56 | BF60: =AK60*AK$4+AQ60*AQ$4+AX60*AX$4+BE60*BE$4 -> 51.25 | BH60: =O60*O$4+T60*T$4+AX$4*AX60+BE60*BE$4 -> 51.25 | BI60: =AX$3*AX60+BE$3*BE60 -> 55 | BJ60: =AW60*AX$3+BD60*BE$3 -> 5 | BK60: =_xlfn.RANK.EQ(BJ60,BJ$8:BJ$63,1) -> 55 | BL60: =AT60/J60*10000 -> 0 | BM60: =_xlfn.RANK.EQ(BL60,BL$8:BL$63,1) -> 15 | BN60: =BA60/J60*10000 -> 0 | BO60: =_xlfn.RANK.EQ(BN60,BN$8:BN$63,1) -> 33 | BP60: =BM60*BL$3+BO60*BN$3 -> 24
D61: Звездный городок | J61: 7620 | K61: 0 | L61: 0 | M61: =L61-K61 -> 0 | N61: =IFERROR(M61/K61,"-") -> - | O61: =_xlfn.RANK.EQ(L61,L$8:L$63,0) -> 47 | P61: 0 | Q61: 0 | R61: =Q61-P61 -> 0 | S61: =IFERROR(R61/P61,"-") -> - | T61: =_xlfn.RANK.EQ(Q61,Q$8:Q$63,0) -> 38 | U61: 0 | V61: 2 | W61: =V61-U61 -> 2 | X61: =IFERROR(W61/U61,"-") -> - | Y61: =_xlfn.RANK.EQ(V61,V$8:V$63,0) -> 53 | Z61: 0 | AA61: 1 | AB61: =AA61-Z61 -> 1 | AC61: =IFERROR(AB61/Z61,"-") -> - | AD61: =_xlfn.RANK.EQ(AA61,AA$8:AA$63,0) -> 55 | AE61: =O61*O$4+T61*T$4+Y61*Y$4+AD61*AD$4 -> 50.55 | AF61: =K61 -> 0 | AG61: =L61 -> 0 | AH61: =AG61-AF61 -> 0 | AI61: =IFERROR(AH61/AF61,"-") -> - | AJ61: =10000*AG61/J61 -> 0 | AK61: =_xlfn.RANK.EQ(AJ61,AJ$8:AJ$63,0) -> 47 | AL61: =P61 -> 0 | AM61: =Q61 -> 0 | AN61: =AM61-AL61 -> 0 | AO61: =IFERROR(AN61/AL61,"-") -> - | AP61: =10000*AM61/J61 -> 0 | AQ61: =_xlfn.RANK.EQ(AP61,AP$8:AP$63,0) -> 38 | AR61: 0 | AS61: 2 | AT61: =AS61-AR61 -> 2 | AU61: =IFERROR(AT61/AR61,"-") -> - | AV61: =10000*AS61/J61 -> 2.6246719 | AW61: =(MAX(AV$8:AV$63)-AV61)/MAX(AV$8:AV$63)*5 -> 4.6939821 | AX61: =_xlfn.RANK.EQ(AV61,AV$8:AV$63,0) -> 50 | AY61: 0 | AZ61: 1 | BA61: =AZ61-AY61 -> 1 | BB61: =IFERROR(BA61/AY61,"-") -> - | BC61: =AZ61*10000/J61 -> 1.312336 | BD61: =(MAX(BC$8:BC$63)-BC61)/MAX(BC$8:BC$63)*5 -> 4.9510576 | BE61: =_xlfn.RANK.EQ(BC61,BC$8:BC$63,0) -> 54 | BF61: =AK61*AK$4+AQ61*AQ$4+AX61*AX$4+BE61*BE$4 -> 49.15 | BH61: =O61*O$4+T61*T$4+AX$4*AX61+BE61*BE$4 -> 49.15 | BI61: =AX$3*AX61+BE$3*BE61 -> 52 | BJ61: =AW61*AX$3+BD61*BE$3 -> 4.8225198 | BK61: =_xlfn.RANK.EQ(BJ61,BJ$8:BJ$63,1) -> 53 | BL61: =AT61/J61*10000 -> 2.6246719 | BM61: =_xlfn.RANK.EQ(BL61,BL$8:BL$63,1) -> 30 | BN61: =BA61/J61*10000 -> 1.312336 | BO61: =_xlfn.RANK.EQ(BN61,BN$8:BN$63,1) -> 36 | BP61: =BM61*BL$3+BO61*BN$3 -> 33
D62: Краснознаменск | J62: 44402 | K62: 0 | L62: 0 | M62: =L62-K62 -> 0 | N62: =IFERROR(M62/K62,"-") -> - | O62: =_xlfn.RANK.EQ(L62,L$8:L$63,0) -> 47 | P62: 0 | Q62: 0 | R62: =Q62-P62 -> 0 | S62: =IFERROR(R62/P62,"-") -> - | T62: =_xlfn.RANK.EQ(Q62,Q$8:Q$63,0) -> 38 | U62: 0 | V62: 11 | W62: =V62-U62 -> 11 | X62: =IFERROR(W62/U62,"-") -> - | Y62: =_xlfn.RANK.EQ(V62,V$8:V$63,0) -> 51 | Z62: 70 | AA62: 58 | AB62: =AA62-Z62 -> -12 | AC62: =IFERROR(AB62/Z62,"-") -> -0.17142857 | AD62: =_xlfn.RANK.EQ(AA62,AA$8:AA$63,0) -> 49 | AE62: =O62*O$4+T62*T$4+Y62*Y$4+AD62*AD$4 -> 47.75 | AF62: =K62 -> 0 | AG62: =L62 -> 0 | AH62: =AG62-AF62 -> 0 | AI62: =IFERROR(AH62/AF62,"-") -> - | AJ62: =10000*AG62/J62 -> 0 | AK62: =_xlfn.RANK.EQ(AJ62,AJ$8:AJ$63,0) -> 47 | AL62: =P62 -> 0 | AM62: =Q62 -> 0 | AN62: =AM62-AL62 -> 0 | AO62: =IFERROR(AN62/AL62,"-") -> - | AP62: =10000*AM62/J62 -> 0 | AQ62: =_xlfn.RANK.EQ(AP62,AP$8:AP$63,0) -> 38 | AR62: 0 | AS62: 11 | AT62: =AS62-AR62 -> 11 | AU62: =IFERROR(AT62/AR62,"-") -> - | AV62: =10000*AS62/J62 -> 2.4773659 | AW62: =(MAX(AV$8:AV$63)-AV62)/MAX(AV$8:AV$63)*5 -> 4.7111569 | AX62: =_xlfn.RANK.EQ(AV62,AV$8:AV$63,0) -> 51 | AY62: 70 | AZ62: 58 | BA62: =AZ62-AY62 -> -12 | BB62: =IFERROR(BA62/AY62,"-") -> -0.17142857 | BC62: =AZ62*10000/J62 -> 13.062475 | BD62: =(MAX(BC$8:BC$63)-BC62)/MAX(BC$8:BC$63)*5 -> 4.5128462 | BE62: =_xlfn.RANK.EQ(BC62,BC$8:BC$63,0) -> 45 | BF62: =AK62*AK$4+AQ62*AQ$4+AX62*AX$4+BE62*BE$4 -> 46.35 | BH62: =O62*O$4+T62*T$4+AX$4*AX62+BE62*BE$4 -> 46.35 | BI62: =AX$3*AX62+BE$3*BE62 -> 48 | BJ62: =AW62*AX$3+BD62*BE$3 -> 4.6120016 | BK62: =_xlfn.RANK.EQ(BJ62,BJ$8:BJ$63,1) -> 47 | BL62: =AT62/J62*10000 -> 2.4773659 | BM62: =_xlfn.RANK.EQ(BL62,BL$8:BL$63,1) -> 28 | BN62: =BA62/J62*10000 -> -2.702581 | BO62: =_xlfn.RANK.EQ(BN62,BN$8:BN$63,1) -> 27 | BP62: =BM62*BL$3+BO62*BN$3 -> 27.5
D63: Молодежный | J63: 2872 | K63: 0 | L63: 0 | M63: =L63-K63 -> 0 | N63: =IFERROR(M63/K63,"-") -> - | O63: =_xlfn.RANK.EQ(L63,L$8:L$63,0) -> 47 | P63: 0 | Q63: 0 | R63: =Q63-P63 -> 0 | S63: =IFERROR(R63/P63,"-") -> - | T63: =_xlfn.RANK.EQ(Q63,Q$8:Q$63,0) -> 38 | U63: 2 | V63: 0 | W63: =V63-U63 -> -2 | X63: =IFERROR(W63/U63,"-") -> -1 | Y63: =_xlfn.RANK.EQ(V63,V$8:V$63,0) -> 54 | Z63: 4 | AA63: 3 | AB63: =AA63-Z63 -> -1 | AC63: =IFERROR(AB63/Z63,"-") -> -0.25 | AD63: =_xlfn.RANK.EQ(AA63,AA$8:AA$63,0) -> 53 | AE63: =O63*O$4+T63*T$4+Y63*Y$4+AD63*AD$4 -> 50.2 | AF63: =K63 -> 0 | AG63: =L63 -> 0 | AH63: =AG63-AF63 -> 0 | AI63: =IFERROR(AH63/AF63,"-") -> - | AJ63: =10000*AG63/J63 -> 0 | AK63: =_xlfn.RANK.EQ(AJ63,AJ$8:AJ$63,0) -> 47 | AL63: =P63 -> 0 | AM63: =Q63 -> 0 | AN63: =AM63-AL63 -> 0 | AO63: =IFERROR(AN63/AL63,"-") -> - | AP63: =10000*AM63/J63 -> 0 | AQ63: =_xlfn.RANK.EQ(AP63,AP$8:AP$63,0) -> 38 | AR63: 2 | AS63: 0 | AT63: =AS63-AR63 -> -2 | AU63: =IFERROR(AT63/AR63,"-") -> -1 | AV63: =10000*AS63/J63 -> 0 | AW63: =(MAX(AV$8:AV$63)-AV63)/MAX(AV$8:AV$63)*5 -> 5 | AX63: =_xlfn.RANK.EQ(AV63,AV$8:AV$63,0) -> 54 | AY63: 4 | AZ63: 3 | BA63: =AZ63-AY63 -> -1 | BB63: =IFERROR(BA63/AY63,"-") -> -0.25 | BC63: =AZ63*10000/J63 -> 10.445682 | BD63: =(MAX(BC$8:BC$63)-BC63)/MAX(BC$8:BC$63)*5 -> 4.6104372 | BE63: =_xlfn.RANK.EQ(BC63,BC$8:BC$63,0) -> 49 | BF63: =AK63*AK$4+AQ63*AQ$4+AX63*AX$4+BE63*BE$4 -> 48.8 | BH63: =O63*O$4+T63*T$4+AX$4*AX63+BE63*BE$4 -> 48.8 | BI63: =AX$3*AX63+BE$3*BE63 -> 51.5 | BJ63: =AW63*AX$3+BD63*BE$3 -> 4.8052186 | BK63: =_xlfn.RANK.EQ(BJ63,BJ$8:BJ$63,1) -> 52 | BL63: =AT63/J63*10000 -> -6.9637883 | BM63: =_xlfn.RANK.EQ(BL63,BL$8:BL$63,1) -> 1 | BN63: =BA63/J63*10000 -> -3.4818942 | BO63: =_xlfn.RANK.EQ(BN63,BN$8:BN$63,1) -> 22 | BP63: =BM63*BL$3+BO63*BN$3 -> 11.5

Sheet 1_Ранг лучших динамика
